2025-01-28 15:13:28,815 - my log - INFO - Guest watch list accessed
2025-01-28 15:14:32,375 - my log - INFO - Login endpoint accessed
2025-01-28 15:14:32,610 - my log - INFO - Login successful for username: rotem
2025-01-28 15:14:32,621 - my log - INFO - Manager dashboard accessed by username: rotem
2025-01-28 15:14:32,623 - my log - INFO - Manager dashboard access granted for username: rotem
2025-01-28 15:14:32,741 - my log - INFO - Fetched 3 customers based on search filters
2025-01-28 15:14:32,748 - my log - INFO - Fetched all active loans
2025-01-28 15:14:32,749 - my log - INFO - Fetched all late loans
2025-01-28 15:14:41,329 - my log - INFO - find book succeded!
2025-01-28 15:14:46,102 - my log - INFO - find book succeded!

2025-01-31 14:43:02,101 - my log - INFO - Guest watch list accessed
2025-01-31 14:43:20,045 - my log - INFO - Login endpoint accessed
2025-01-31 14:43:20,354 - my log - INFO - Login successful for username: rotem
2025-01-31 14:43:20,367 - my log - INFO - Manager dashboard accessed by username: rotem
2025-01-31 14:43:20,368 - my log - INFO - Manager dashboard access granted for username: rotem
2025-01-31 14:43:20,583 - my log - INFO - Fetched all late loans
2025-01-31 14:43:20,584 - my log - INFO - Fetched all active loans
2025-01-31 14:43:20,592 - my log - INFO - Fetched 3 customers based on search filters
2025-01-31 14:44:58,075 - my log - INFO - Login endpoint accessed
2025-01-31 14:44:58,376 - my log - INFO - Login successful for username: orel
2025-01-31 14:44:58,388 - my log - INFO - User dashboard accessed by username: orel
2025-01-31 14:44:58,390 - my log - INFO - User dashboard access granted for username: orel
2025-01-31 14:44:59,165 - my log - INFO - findCustomersBooks accessed by username: orel
2025-01-31 14:44:59,177 - my log - INFO - Loaned books retrieved for username: orel2025-02-11 00:02:56,068 - my log - INFO - Login endpoint accessed
2025-02-11 00:02:56,473 - my log - WARNING - Invalid login attempt for username: orel
2025-02-11 00:03:06,657 - my log - INFO - Login endpoint accessed
2025-02-11 00:03:07,384 - my log - INFO - Login successful for username: orel
2025-02-11 00:03:07,401 - my log - INFO - User dashboard accessed by username: orel
2025-02-11 00:03:07,404 - my log - INFO - User dashboard access granted for username: orel
2025-02-11 00:03:08,172 - my log - INFO - findCustomersBooks accessed by username: orel
2025-02-11 00:03:08,187 - my log - INFO - Loaned books retrieved for username: orel
2025-02-11 00:03:38,288 - my log - INFO - Login endpoint accessed
2025-02-11 00:03:39,263 - my log - INFO - Login successful for username: rotem
2025-02-11 00:03:39,293 - my log - INFO - Manager dashboard accessed by username: rotem
2025-02-11 00:03:39,303 - my log - INFO - Manager dashboard access granted for username: rotem
2025-02-11 00:03:39,562 - my log - INFO - Fetched 3 customers based on search filters
2025-02-11 00:03:39,568 - my log - INFO - Fetched all active loans
2025-02-11 00:03:39,570 - my log - INFO - Fetched all late loans
2025-02-11 00:04:43,604 - my log - INFO - Guest watch list accessed
2025-02-16 19:27:19,245 - my log - INFO - Signup endpoint accessed
2025-02-16 19:27:20,749 - my log - INFO - New customer added: <Customer(id=1, firstName=Maya, lastName=Levi, city=new york, age=20, birthDate=2004-12-01, active=True, phoneNumber=058-5215501, email=maya@gmail.com, role=user, username=maya, password=$2b$12$LE4nT.VPts/If3xjFJOFTOa9NsLJO67sjgEcjNgHdHK7OqnRxQH..)>
2025-02-16 19:27:32,751 - my log - INFO - Login endpoint accessed
2025-02-16 19:27:34,292 - my log - INFO - Login successful for username: maya
2025-02-16 19:27:34,304 - my log - INFO - User dashboard accessed by username: maya
2025-02-16 19:27:35,521 - my log - INFO - User dashboard access granted for username: maya
2025-02-16 19:27:36,006 - my log - INFO - findCustomersBooks accessed by username: maya
2025-02-16 19:27:37,359 - my log - INFO - Loaned books retrieved for username: maya
2025-02-16 19:32:04,010 - my log - INFO - findCustomersBooks accessed by username: maya
2025-02-16 19:32:05,497 - my log - INFO - Loaned books retrieved for username: maya
2025-02-16 19:32:13,767 - my log - INFO - Guest watch list accessed
2025-02-16 19:32:32,438 - my log - INFO - Login endpoint accessed
2025-02-16 19:32:32,924 - my log - INFO - Login successful for username: maya
2025-02-16 19:32:32,935 - my log - INFO - Manager dashboard accessed by username: maya
2025-02-16 19:32:33,222 - my log - INFO - Manager dashboard access granted for username: maya
2025-02-16 19:32:33,707 - my log - INFO - Fetched 0 customers based on search filters
2025-02-16 19:32:34,660 - my log - INFO - Fetched all late loans
2025-02-16 19:32:34,752 - my log - INFO - Fetched all active loans
2025-02-16 19:35:13,828 - my log - INFO - Fetched all late loans
2025-02-16 19:35:13,855 - my log - INFO - Fetched 0 customers based on search filters
2025-02-16 19:35:14,690 - my log - INFO - Fetched all active loans
2025-02-16 19:35:28,167 - my log - INFO - Fetched all active loans
2025-02-16 19:35:28,168 - my log - INFO - Fetched all late loans
2025-02-16 19:35:28,168 - my log - INFO - Fetched 0 customers based on search filters
2025-02-16 19:35:37,394 - my log - INFO - Fetched 0 customers based on search filters
2025-02-16 19:35:38,313 - my log - INFO - Fetched all late loans
2025-02-16 19:35:38,315 - my log - INFO - Fetched all active loans
2025-02-16 19:35:51,486 - my log - INFO - Fetched all late loans
2025-02-16 19:35:51,506 - my log - INFO - Fetched 0 customers based on search filters
2025-02-16 19:35:51,508 - my log - INFO - Fetched all active loans
2025-02-16 19:36:04,538 - my log - INFO - Fetched all active loans
2025-02-16 19:36:04,541 - my log - INFO - Fetched 0 customers based on search filters
2025-02-16 19:36:04,542 - my log - INFO - Fetched all late loans
2025-02-16 19:36:07,026 - my log - INFO - Fetched 0 customers based on search filters
2025-02-16 19:36:07,041 - my log - INFO - Fetched all late loans
2025-02-16 19:36:09,462 - my log - INFO - Fetched all active loans
2025-02-16 19:36:14,945 - my log - INFO - Fetched 0 customers based on search filters
2025-02-16 19:36:14,958 - my log - INFO - Fetched all active loans
2025-02-16 19:36:14,959 - my log - INFO - Fetched all late loans
2025-02-16 19:40:26,525 - my log - INFO - Fetched all active loans
2025-02-16 19:40:26,526 - my log - INFO - Fetched all late loans
2025-02-16 19:40:26,534 - my log - INFO - Fetched 0 customers based on search filters
2025-02-16 19:40:28,551 - my log - INFO - Fetched 0 customers based on search filters
2025-02-16 19:40:29,535 - my log - INFO - Fetched all active loans
2025-02-16 19:40:29,536 - my log - INFO - Fetched all late loans
2025-02-16 19:46:37,043 - my log - INFO - Fetched 0 customers based on search filters
2025-02-16 19:46:37,059 - my log - INFO - Fetched all active loans
2025-02-16 19:46:37,060 - my log - INFO - Fetched all late loans
2025-02-16 19:46:55,546 - my log - INFO - Login endpoint accessed
2025-02-16 19:46:57,066 - my log - INFO - Login successful for username: maya
2025-02-16 19:46:57,077 - my log - INFO - Manager dashboard accessed by username: maya
2025-02-16 19:46:58,233 - my log - INFO - Manager dashboard access granted for username: maya
2025-02-16 19:46:58,351 - sqlalchemy.pool.impl.QueuePool - ERROR - Exception during reset or similar
Traceback (most recent call last):
  File "C:\Users\mayal\OneDrive\מסמכים\JB\pyt\SQLITE PCT\trying\projectNumber1\env\Lib\site-packages\sqlalchemy\pool\base.py", line 986, in _finalize_fairy
    fairy._reset(
    ~~~~~~~~~~~~^
        pool,
        ^^^^^
    ...<2 lines>...
        asyncio_safe=can_manipulate_connection,
        ^^^^^^^^^^^^^^^^^^^^^^^^^^^^^^^^^^^^^^^
    )
    ^
  File "C:\Users\mayal\OneDrive\מסמכים\JB\pyt\SQLITE PCT\trying\projectNumber1\env\Lib\site-packages\sqlalchemy\pool\base.py", line 1432, in _reset
    pool._dialect.do_rollback(self)
    ~~~~~~~~~~~~~~~~~~~~~~~~~^^^^^^
  File "C:\Users\mayal\OneDrive\מסמכים\JB\pyt\SQLITE PCT\trying\projectNumber1\env\Lib\site-packages\sqlalchemy\engine\default.py", line 700, in do_rollback
    dbapi_connection.rollback()
    ~~~~~~~~~~~~~~~~~~~~~~~~~^^
psycopg2.OperationalError: SSL connection has been closed unexpectedly

2025-02-16 19:46:58,396 - sqlalchemy.pool.impl.QueuePool - ERROR - Exception during reset or similar
Traceback (most recent call last):
  File "C:\Users\mayal\OneDrive\מסמכים\JB\pyt\SQLITE PCT\trying\projectNumber1\env\Lib\site-packages\sqlalchemy\pool\base.py", line 986, in _finalize_fairy
    fairy._reset(
    ~~~~~~~~~~~~^
        pool,
        ^^^^^
    ...<2 lines>...
        asyncio_safe=can_manipulate_connection,
        ^^^^^^^^^^^^^^^^^^^^^^^^^^^^^^^^^^^^^^^
    )
    ^
  File "C:\Users\mayal\OneDrive\מסמכים\JB\pyt\SQLITE PCT\trying\projectNumber1\env\Lib\site-packages\sqlalchemy\pool\base.py", line 1432, in _reset
    pool._dialect.do_rollback(self)
    ~~~~~~~~~~~~~~~~~~~~~~~~~^^^^^^
  File "C:\Users\mayal\OneDrive\מסמכים\JB\pyt\SQLITE PCT\trying\projectNumber1\env\Lib\site-packages\sqlalchemy\engine\default.py", line 700, in do_rollback
    dbapi_connection.rollback()
    ~~~~~~~~~~~~~~~~~~~~~~~~~^^
psycopg2.OperationalError: SSL connection has been closed unexpectedly

2025-02-16 19:46:58,398 - sqlalchemy.pool.impl.QueuePool - ERROR - Exception during reset or similar
Traceback (most recent call last):
  File "C:\Users\mayal\OneDrive\מסמכים\JB\pyt\SQLITE PCT\trying\projectNumber1\env\Lib\site-packages\sqlalchemy\pool\base.py", line 986, in _finalize_fairy
    fairy._reset(
    ~~~~~~~~~~~~^
        pool,
        ^^^^^
    ...<2 lines>...
        asyncio_safe=can_manipulate_connection,
        ^^^^^^^^^^^^^^^^^^^^^^^^^^^^^^^^^^^^^^^
    )
    ^
  File "C:\Users\mayal\OneDrive\מסמכים\JB\pyt\SQLITE PCT\trying\projectNumber1\env\Lib\site-packages\sqlalchemy\pool\base.py", line 1432, in _reset
    pool._dialect.do_rollback(self)
    ~~~~~~~~~~~~~~~~~~~~~~~~~^^^^^^
  File "C:\Users\mayal\OneDrive\מסמכים\JB\pyt\SQLITE PCT\trying\projectNumber1\env\Lib\site-packages\sqlalchemy\engine\default.py", line 700, in do_rollback
    dbapi_connection.rollback()
    ~~~~~~~~~~~~~~~~~~~~~~~~~^^
psycopg2.OperationalError: SSL connection has been closed unexpectedly

2025-02-16 19:46:58,399 - sqlalchemy.pool.impl.QueuePool - ERROR - Exception during reset or similar
Traceback (most recent call last):
  File "C:\Users\mayal\OneDrive\מסמכים\JB\pyt\SQLITE PCT\trying\projectNumber1\env\Lib\site-packages\sqlalchemy\pool\base.py", line 986, in _finalize_fairy
    fairy._reset(
    ~~~~~~~~~~~~^
        pool,
        ^^^^^
    ...<2 lines>...
        asyncio_safe=can_manipulate_connection,
        ^^^^^^^^^^^^^^^^^^^^^^^^^^^^^^^^^^^^^^^
    )
    ^
  File "C:\Users\mayal\OneDrive\מסמכים\JB\pyt\SQLITE PCT\trying\projectNumber1\env\Lib\site-packages\sqlalchemy\pool\base.py", line 1432, in _reset
    pool._dialect.do_rollback(self)
    ~~~~~~~~~~~~~~~~~~~~~~~~~^^^^^^
  File "C:\Users\mayal\OneDrive\מסמכים\JB\pyt\SQLITE PCT\trying\projectNumber1\env\Lib\site-packages\sqlalchemy\engine\default.py", line 700, in do_rollback
    dbapi_connection.rollback()
    ~~~~~~~~~~~~~~~~~~~~~~~~~^^
psycopg2.OperationalError: SSL connection has been closed unexpectedly

2025-02-16 19:46:58,402 - sqlalchemy.pool.impl.QueuePool - ERROR - Exception during reset or similar
Traceback (most recent call last):
  File "C:\Users\mayal\OneDrive\מסמכים\JB\pyt\SQLITE PCT\trying\projectNumber1\env\Lib\site-packages\sqlalchemy\pool\base.py", line 986, in _finalize_fairy
    fairy._reset(
    ~~~~~~~~~~~~^
        pool,
        ^^^^^
    ...<2 lines>...
        asyncio_safe=can_manipulate_connection,
        ^^^^^^^^^^^^^^^^^^^^^^^^^^^^^^^^^^^^^^^
    )
    ^
  File "C:\Users\mayal\OneDrive\מסמכים\JB\pyt\SQLITE PCT\trying\projectNumber1\env\Lib\site-packages\sqlalchemy\pool\base.py", line 1432, in _reset
    pool._dialect.do_rollback(self)
    ~~~~~~~~~~~~~~~~~~~~~~~~~^^^^^^
  File "C:\Users\mayal\OneDrive\מסמכים\JB\pyt\SQLITE PCT\trying\projectNumber1\env\Lib\site-packages\sqlalchemy\engine\default.py", line 700, in do_rollback
    dbapi_connection.rollback()
    ~~~~~~~~~~~~~~~~~~~~~~~~~^^
psycopg2.OperationalError: SSL connection has been closed unexpectedly

2025-02-16 19:46:58,404 - sqlalchemy.pool.impl.QueuePool - ERROR - Exception during reset or similar
Traceback (most recent call last):
  File "C:\Users\mayal\OneDrive\מסמכים\JB\pyt\SQLITE PCT\trying\projectNumber1\env\Lib\site-packages\sqlalchemy\pool\base.py", line 986, in _finalize_fairy
    fairy._reset(
    ~~~~~~~~~~~~^
        pool,
        ^^^^^
    ...<2 lines>...
        asyncio_safe=can_manipulate_connection,
        ^^^^^^^^^^^^^^^^^^^^^^^^^^^^^^^^^^^^^^^
    )
    ^
  File "C:\Users\mayal\OneDrive\מסמכים\JB\pyt\SQLITE PCT\trying\projectNumber1\env\Lib\site-packages\sqlalchemy\pool\base.py", line 1432, in _reset
    pool._dialect.do_rollback(self)
    ~~~~~~~~~~~~~~~~~~~~~~~~~^^^^^^
  File "C:\Users\mayal\OneDrive\מסמכים\JB\pyt\SQLITE PCT\trying\projectNumber1\env\Lib\site-packages\sqlalchemy\engine\default.py", line 700, in do_rollback
    dbapi_connection.rollback()
    ~~~~~~~~~~~~~~~~~~~~~~~~~^^
psycopg2.OperationalError: SSL connection has been closed unexpectedly

2025-02-16 19:46:58,405 - sqlalchemy.pool.impl.QueuePool - ERROR - Exception during reset or similar
Traceback (most recent call last):
  File "C:\Users\mayal\OneDrive\מסמכים\JB\pyt\SQLITE PCT\trying\projectNumber1\env\Lib\site-packages\sqlalchemy\pool\base.py", line 986, in _finalize_fairy
    fairy._reset(
    ~~~~~~~~~~~~^
        pool,
        ^^^^^
    ...<2 lines>...
        asyncio_safe=can_manipulate_connection,
        ^^^^^^^^^^^^^^^^^^^^^^^^^^^^^^^^^^^^^^^
    )
    ^
  File "C:\Users\mayal\OneDrive\מסמכים\JB\pyt\SQLITE PCT\trying\projectNumber1\env\Lib\site-packages\sqlalchemy\pool\base.py", line 1432, in _reset
    pool._dialect.do_rollback(self)
    ~~~~~~~~~~~~~~~~~~~~~~~~~^^^^^^
  File "C:\Users\mayal\OneDrive\מסמכים\JB\pyt\SQLITE PCT\trying\projectNumber1\env\Lib\site-packages\sqlalchemy\engine\default.py", line 700, in do_rollback
    dbapi_connection.rollback()
    ~~~~~~~~~~~~~~~~~~~~~~~~~^^
psycopg2.OperationalError: SSL connection has been closed unexpectedly

2025-02-16 19:46:58,407 - sqlalchemy.pool.impl.QueuePool - ERROR - Exception during reset or similar
Traceback (most recent call last):
  File "C:\Users\mayal\OneDrive\מסמכים\JB\pyt\SQLITE PCT\trying\projectNumber1\env\Lib\site-packages\sqlalchemy\pool\base.py", line 986, in _finalize_fairy
    fairy._reset(
    ~~~~~~~~~~~~^
        pool,
        ^^^^^
    ...<2 lines>...
        asyncio_safe=can_manipulate_connection,
        ^^^^^^^^^^^^^^^^^^^^^^^^^^^^^^^^^^^^^^^
    )
    ^
  File "C:\Users\mayal\OneDrive\מסמכים\JB\pyt\SQLITE PCT\trying\projectNumber1\env\Lib\site-packages\sqlalchemy\pool\base.py", line 1432, in _reset
    pool._dialect.do_rollback(self)
    ~~~~~~~~~~~~~~~~~~~~~~~~~^^^^^^
  File "C:\Users\mayal\OneDrive\מסמכים\JB\pyt\SQLITE PCT\trying\projectNumber1\env\Lib\site-packages\sqlalchemy\engine\default.py", line 700, in do_rollback
    dbapi_connection.rollback()
    ~~~~~~~~~~~~~~~~~~~~~~~~~^^
psycopg2.OperationalError: SSL connection has been closed unexpectedly

2025-02-16 19:46:58,408 - sqlalchemy.pool.impl.QueuePool - ERROR - Exception during reset or similar
Traceback (most recent call last):
  File "C:\Users\mayal\OneDrive\מסמכים\JB\pyt\SQLITE PCT\trying\projectNumber1\env\Lib\site-packages\sqlalchemy\pool\base.py", line 986, in _finalize_fairy
    fairy._reset(
    ~~~~~~~~~~~~^
        pool,
        ^^^^^
    ...<2 lines>...
        asyncio_safe=can_manipulate_connection,
        ^^^^^^^^^^^^^^^^^^^^^^^^^^^^^^^^^^^^^^^
    )
    ^
  File "C:\Users\mayal\OneDrive\מסמכים\JB\pyt\SQLITE PCT\trying\projectNumber1\env\Lib\site-packages\sqlalchemy\pool\base.py", line 1432, in _reset
    pool._dialect.do_rollback(self)
    ~~~~~~~~~~~~~~~~~~~~~~~~~^^^^^^
  File "C:\Users\mayal\OneDrive\מסמכים\JB\pyt\SQLITE PCT\trying\projectNumber1\env\Lib\site-packages\sqlalchemy\engine\default.py", line 700, in do_rollback
    dbapi_connection.rollback()
    ~~~~~~~~~~~~~~~~~~~~~~~~~^^
psycopg2.OperationalError: SSL connection has been closed unexpectedly

2025-02-16 19:46:58,409 - sqlalchemy.pool.impl.QueuePool - ERROR - Exception during reset or similar
Traceback (most recent call last):
  File "C:\Users\mayal\OneDrive\מסמכים\JB\pyt\SQLITE PCT\trying\projectNumber1\env\Lib\site-packages\sqlalchemy\pool\base.py", line 986, in _finalize_fairy
    fairy._reset(
    ~~~~~~~~~~~~^
        pool,
        ^^^^^
    ...<2 lines>...
        asyncio_safe=can_manipulate_connection,
        ^^^^^^^^^^^^^^^^^^^^^^^^^^^^^^^^^^^^^^^
    )
    ^
  File "C:\Users\mayal\OneDrive\מסמכים\JB\pyt\SQLITE PCT\trying\projectNumber1\env\Lib\site-packages\sqlalchemy\pool\base.py", line 1432, in _reset
    pool._dialect.do_rollback(self)
    ~~~~~~~~~~~~~~~~~~~~~~~~~^^^^^^
  File "C:\Users\mayal\OneDrive\מסמכים\JB\pyt\SQLITE PCT\trying\projectNumber1\env\Lib\site-packages\sqlalchemy\engine\default.py", line 700, in do_rollback
    dbapi_connection.rollback()
    ~~~~~~~~~~~~~~~~~~~~~~~~~^^
psycopg2.OperationalError: SSL connection has been closed unexpectedly

2025-02-16 19:46:58,411 - sqlalchemy.pool.impl.QueuePool - ERROR - Exception during reset or similar
Traceback (most recent call last):
  File "C:\Users\mayal\OneDrive\מסמכים\JB\pyt\SQLITE PCT\trying\projectNumber1\env\Lib\site-packages\sqlalchemy\pool\base.py", line 986, in _finalize_fairy
    fairy._reset(
    ~~~~~~~~~~~~^
        pool,
        ^^^^^
    ...<2 lines>...
        asyncio_safe=can_manipulate_connection,
        ^^^^^^^^^^^^^^^^^^^^^^^^^^^^^^^^^^^^^^^
    )
    ^
  File "C:\Users\mayal\OneDrive\מסמכים\JB\pyt\SQLITE PCT\trying\projectNumber1\env\Lib\site-packages\sqlalchemy\pool\base.py", line 1432, in _reset
    pool._dialect.do_rollback(self)
    ~~~~~~~~~~~~~~~~~~~~~~~~~^^^^^^
  File "C:\Users\mayal\OneDrive\מסמכים\JB\pyt\SQLITE PCT\trying\projectNumber1\env\Lib\site-packages\sqlalchemy\engine\default.py", line 700, in do_rollback
    dbapi_connection.rollback()
    ~~~~~~~~~~~~~~~~~~~~~~~~~^^
psycopg2.OperationalError: SSL connection has been closed unexpectedly

2025-02-16 19:46:58,412 - sqlalchemy.pool.impl.QueuePool - ERROR - Exception during reset or similar
Traceback (most recent call last):
  File "C:\Users\mayal\OneDrive\מסמכים\JB\pyt\SQLITE PCT\trying\projectNumber1\env\Lib\site-packages\sqlalchemy\pool\base.py", line 986, in _finalize_fairy
    fairy._reset(
    ~~~~~~~~~~~~^
        pool,
        ^^^^^
    ...<2 lines>...
        asyncio_safe=can_manipulate_connection,
        ^^^^^^^^^^^^^^^^^^^^^^^^^^^^^^^^^^^^^^^
    )
    ^
  File "C:\Users\mayal\OneDrive\מסמכים\JB\pyt\SQLITE PCT\trying\projectNumber1\env\Lib\site-packages\sqlalchemy\pool\base.py", line 1432, in _reset
    pool._dialect.do_rollback(self)
    ~~~~~~~~~~~~~~~~~~~~~~~~~^^^^^^
  File "C:\Users\mayal\OneDrive\מסמכים\JB\pyt\SQLITE PCT\trying\projectNumber1\env\Lib\site-packages\sqlalchemy\engine\default.py", line 700, in do_rollback
    dbapi_connection.rollback()
    ~~~~~~~~~~~~~~~~~~~~~~~~~^^
psycopg2.OperationalError: SSL connection has been closed unexpectedly

2025-02-16 19:46:59,500 - my log - INFO - Fetched 0 customers based on search filters
2025-02-16 19:46:59,610 - my log - INFO - Fetched all active loans
2025-02-16 19:47:00,456 - my log - INFO - Fetched all late loans
2025-02-16 19:47:22,765 - my log - INFO - Fetched all active loans
2025-02-16 19:47:22,793 - my log - INFO - Fetched all late loans
2025-02-16 19:47:22,825 - my log - INFO - Fetched 0 customers based on search filters
2025-02-16 19:47:51,687 - sqlalchemy.pool.impl.QueuePool - ERROR - Exception during reset or similar
Traceback (most recent call last):
  File "C:\Users\mayal\OneDrive\מסמכים\JB\pyt\SQLITE PCT\trying\projectNumber1\env\Lib\site-packages\sqlalchemy\pool\base.py", line 986, in _finalize_fairy
    fairy._reset(
    ~~~~~~~~~~~~^
        pool,
        ^^^^^
    ...<2 lines>...
        asyncio_safe=can_manipulate_connection,
        ^^^^^^^^^^^^^^^^^^^^^^^^^^^^^^^^^^^^^^^
    )
    ^
  File "C:\Users\mayal\OneDrive\מסמכים\JB\pyt\SQLITE PCT\trying\projectNumber1\env\Lib\site-packages\sqlalchemy\pool\base.py", line 1432, in _reset
    pool._dialect.do_rollback(self)
    ~~~~~~~~~~~~~~~~~~~~~~~~~^^^^^^
  File "C:\Users\mayal\OneDrive\מסמכים\JB\pyt\SQLITE PCT\trying\projectNumber1\env\Lib\site-packages\sqlalchemy\engine\default.py", line 700, in do_rollback
    dbapi_connection.rollback()
    ~~~~~~~~~~~~~~~~~~~~~~~~~^^
psycopg2.OperationalError: SSL connection has been closed unexpectedly

2025-02-16 19:47:51,688 - sqlalchemy.pool.impl.QueuePool - ERROR - Exception during reset or similar
Traceback (most recent call last):
  File "C:\Users\mayal\OneDrive\מסמכים\JB\pyt\SQLITE PCT\trying\projectNumber1\env\Lib\site-packages\sqlalchemy\pool\base.py", line 986, in _finalize_fairy
    fairy._reset(
    ~~~~~~~~~~~~^
        pool,
        ^^^^^
    ...<2 lines>...
        asyncio_safe=can_manipulate_connection,
        ^^^^^^^^^^^^^^^^^^^^^^^^^^^^^^^^^^^^^^^
    )
    ^
  File "C:\Users\mayal\OneDrive\מסמכים\JB\pyt\SQLITE PCT\trying\projectNumber1\env\Lib\site-packages\sqlalchemy\pool\base.py", line 1432, in _reset
    pool._dialect.do_rollback(self)
    ~~~~~~~~~~~~~~~~~~~~~~~~~^^^^^^
  File "C:\Users\mayal\OneDrive\מסמכים\JB\pyt\SQLITE PCT\trying\projectNumber1\env\Lib\site-packages\sqlalchemy\engine\default.py", line 700, in do_rollback
    dbapi_connection.rollback()
    ~~~~~~~~~~~~~~~~~~~~~~~~~^^
psycopg2.OperationalError: SSL connection has been closed unexpectedly

2025-02-16 19:47:51,689 - sqlalchemy.pool.impl.QueuePool - ERROR - Exception during reset or similar
Traceback (most recent call last):
  File "C:\Users\mayal\OneDrive\מסמכים\JB\pyt\SQLITE PCT\trying\projectNumber1\env\Lib\site-packages\sqlalchemy\pool\base.py", line 986, in _finalize_fairy
    fairy._reset(
    ~~~~~~~~~~~~^
        pool,
        ^^^^^
    ...<2 lines>...
        asyncio_safe=can_manipulate_connection,
        ^^^^^^^^^^^^^^^^^^^^^^^^^^^^^^^^^^^^^^^
    )
    ^
  File "C:\Users\mayal\OneDrive\מסמכים\JB\pyt\SQLITE PCT\trying\projectNumber1\env\Lib\site-packages\sqlalchemy\pool\base.py", line 1432, in _reset
    pool._dialect.do_rollback(self)
    ~~~~~~~~~~~~~~~~~~~~~~~~~^^^^^^
  File "C:\Users\mayal\OneDrive\מסמכים\JB\pyt\SQLITE PCT\trying\projectNumber1\env\Lib\site-packages\sqlalchemy\engine\default.py", line 700, in do_rollback
    dbapi_connection.rollback()
    ~~~~~~~~~~~~~~~~~~~~~~~~~^^
psycopg2.OperationalError: SSL connection has been closed unexpectedly

2025-02-16 19:47:51,690 - sqlalchemy.pool.impl.QueuePool - ERROR - Exception during reset or similar
Traceback (most recent call last):
  File "C:\Users\mayal\OneDrive\מסמכים\JB\pyt\SQLITE PCT\trying\projectNumber1\env\Lib\site-packages\sqlalchemy\pool\base.py", line 986, in _finalize_fairy
    fairy._reset(
    ~~~~~~~~~~~~^
        pool,
        ^^^^^
    ...<2 lines>...
        asyncio_safe=can_manipulate_connection,
        ^^^^^^^^^^^^^^^^^^^^^^^^^^^^^^^^^^^^^^^
    )
    ^
  File "C:\Users\mayal\OneDrive\מסמכים\JB\pyt\SQLITE PCT\trying\projectNumber1\env\Lib\site-packages\sqlalchemy\pool\base.py", line 1432, in _reset
    pool._dialect.do_rollback(self)
    ~~~~~~~~~~~~~~~~~~~~~~~~~^^^^^^
  File "C:\Users\mayal\OneDrive\מסמכים\JB\pyt\SQLITE PCT\trying\projectNumber1\env\Lib\site-packages\sqlalchemy\engine\default.py", line 700, in do_rollback
    dbapi_connection.rollback()
    ~~~~~~~~~~~~~~~~~~~~~~~~~^^
psycopg2.OperationalError: SSL connection has been closed unexpectedly

2025-02-16 19:47:51,690 - sqlalchemy.pool.impl.QueuePool - ERROR - Exception during reset or similar
Traceback (most recent call last):
  File "C:\Users\mayal\OneDrive\מסמכים\JB\pyt\SQLITE PCT\trying\projectNumber1\env\Lib\site-packages\sqlalchemy\pool\base.py", line 986, in _finalize_fairy
    fairy._reset(
    ~~~~~~~~~~~~^
        pool,
        ^^^^^
    ...<2 lines>...
        asyncio_safe=can_manipulate_connection,
        ^^^^^^^^^^^^^^^^^^^^^^^^^^^^^^^^^^^^^^^
    )
    ^
  File "C:\Users\mayal\OneDrive\מסמכים\JB\pyt\SQLITE PCT\trying\projectNumber1\env\Lib\site-packages\sqlalchemy\pool\base.py", line 1432, in _reset
    pool._dialect.do_rollback(self)
    ~~~~~~~~~~~~~~~~~~~~~~~~~^^^^^^
  File "C:\Users\mayal\OneDrive\מסמכים\JB\pyt\SQLITE PCT\trying\projectNumber1\env\Lib\site-packages\sqlalchemy\engine\default.py", line 700, in do_rollback
    dbapi_connection.rollback()
    ~~~~~~~~~~~~~~~~~~~~~~~~~^^
psycopg2.OperationalError: SSL connection has been closed unexpectedly

2025-02-16 19:47:51,691 - sqlalchemy.pool.impl.QueuePool - ERROR - Exception during reset or similar
Traceback (most recent call last):
  File "C:\Users\mayal\OneDrive\מסמכים\JB\pyt\SQLITE PCT\trying\projectNumber1\env\Lib\site-packages\sqlalchemy\pool\base.py", line 986, in _finalize_fairy
    fairy._reset(
    ~~~~~~~~~~~~^
        pool,
        ^^^^^
    ...<2 lines>...
        asyncio_safe=can_manipulate_connection,
        ^^^^^^^^^^^^^^^^^^^^^^^^^^^^^^^^^^^^^^^
    )
    ^
  File "C:\Users\mayal\OneDrive\מסמכים\JB\pyt\SQLITE PCT\trying\projectNumber1\env\Lib\site-packages\sqlalchemy\pool\base.py", line 1432, in _reset
    pool._dialect.do_rollback(self)
    ~~~~~~~~~~~~~~~~~~~~~~~~~^^^^^^
  File "C:\Users\mayal\OneDrive\מסמכים\JB\pyt\SQLITE PCT\trying\projectNumber1\env\Lib\site-packages\sqlalchemy\engine\default.py", line 700, in do_rollback
    dbapi_connection.rollback()
    ~~~~~~~~~~~~~~~~~~~~~~~~~^^
psycopg2.OperationalError: SSL connection has been closed unexpectedly

2025-02-16 19:47:51,692 - sqlalchemy.pool.impl.QueuePool - ERROR - Exception during reset or similar
Traceback (most recent call last):
  File "C:\Users\mayal\OneDrive\מסמכים\JB\pyt\SQLITE PCT\trying\projectNumber1\env\Lib\site-packages\sqlalchemy\pool\base.py", line 986, in _finalize_fairy
    fairy._reset(
    ~~~~~~~~~~~~^
        pool,
        ^^^^^
    ...<2 lines>...
        asyncio_safe=can_manipulate_connection,
        ^^^^^^^^^^^^^^^^^^^^^^^^^^^^^^^^^^^^^^^
    )
    ^
  File "C:\Users\mayal\OneDrive\מסמכים\JB\pyt\SQLITE PCT\trying\projectNumber1\env\Lib\site-packages\sqlalchemy\pool\base.py", line 1432, in _reset
    pool._dialect.do_rollback(self)
    ~~~~~~~~~~~~~~~~~~~~~~~~~^^^^^^
  File "C:\Users\mayal\OneDrive\מסמכים\JB\pyt\SQLITE PCT\trying\projectNumber1\env\Lib\site-packages\sqlalchemy\engine\default.py", line 700, in do_rollback
    dbapi_connection.rollback()
    ~~~~~~~~~~~~~~~~~~~~~~~~~^^
psycopg2.OperationalError: SSL connection has been closed unexpectedly

2025-02-16 19:47:51,693 - sqlalchemy.pool.impl.QueuePool - ERROR - Exception during reset or similar
Traceback (most recent call last):
  File "C:\Users\mayal\OneDrive\מסמכים\JB\pyt\SQLITE PCT\trying\projectNumber1\env\Lib\site-packages\sqlalchemy\pool\base.py", line 986, in _finalize_fairy
    fairy._reset(
    ~~~~~~~~~~~~^
        pool,
        ^^^^^
    ...<2 lines>...
        asyncio_safe=can_manipulate_connection,
        ^^^^^^^^^^^^^^^^^^^^^^^^^^^^^^^^^^^^^^^
    )
    ^
  File "C:\Users\mayal\OneDrive\מסמכים\JB\pyt\SQLITE PCT\trying\projectNumber1\env\Lib\site-packages\sqlalchemy\pool\base.py", line 1432, in _reset
    pool._dialect.do_rollback(self)
    ~~~~~~~~~~~~~~~~~~~~~~~~~^^^^^^
  File "C:\Users\mayal\OneDrive\מסמכים\JB\pyt\SQLITE PCT\trying\projectNumber1\env\Lib\site-packages\sqlalchemy\engine\default.py", line 700, in do_rollback
    dbapi_connection.rollback()
    ~~~~~~~~~~~~~~~~~~~~~~~~~^^
psycopg2.OperationalError: SSL connection has been closed unexpectedly

2025-02-16 19:47:51,694 - sqlalchemy.pool.impl.QueuePool - ERROR - Exception during reset or similar
Traceback (most recent call last):
  File "C:\Users\mayal\OneDrive\מסמכים\JB\pyt\SQLITE PCT\trying\projectNumber1\env\Lib\site-packages\sqlalchemy\pool\base.py", line 986, in _finalize_fairy
    fairy._reset(
    ~~~~~~~~~~~~^
        pool,
        ^^^^^
    ...<2 lines>...
        asyncio_safe=can_manipulate_connection,
        ^^^^^^^^^^^^^^^^^^^^^^^^^^^^^^^^^^^^^^^
    )
    ^
  File "C:\Users\mayal\OneDrive\מסמכים\JB\pyt\SQLITE PCT\trying\projectNumber1\env\Lib\site-packages\sqlalchemy\pool\base.py", line 1432, in _reset
    pool._dialect.do_rollback(self)
    ~~~~~~~~~~~~~~~~~~~~~~~~~^^^^^^
  File "C:\Users\mayal\OneDrive\מסמכים\JB\pyt\SQLITE PCT\trying\projectNumber1\env\Lib\site-packages\sqlalchemy\engine\default.py", line 700, in do_rollback
    dbapi_connection.rollback()
    ~~~~~~~~~~~~~~~~~~~~~~~~~^^
psycopg2.OperationalError: SSL connection has been closed unexpectedly

2025-02-16 19:47:51,694 - sqlalchemy.pool.impl.QueuePool - ERROR - Exception during reset or similar
Traceback (most recent call last):
  File "C:\Users\mayal\OneDrive\מסמכים\JB\pyt\SQLITE PCT\trying\projectNumber1\env\Lib\site-packages\sqlalchemy\pool\base.py", line 986, in _finalize_fairy
    fairy._reset(
    ~~~~~~~~~~~~^
        pool,
        ^^^^^
    ...<2 lines>...
        asyncio_safe=can_manipulate_connection,
        ^^^^^^^^^^^^^^^^^^^^^^^^^^^^^^^^^^^^^^^
    )
    ^
  File "C:\Users\mayal\OneDrive\מסמכים\JB\pyt\SQLITE PCT\trying\projectNumber1\env\Lib\site-packages\sqlalchemy\pool\base.py", line 1432, in _reset
    pool._dialect.do_rollback(self)
    ~~~~~~~~~~~~~~~~~~~~~~~~~^^^^^^
  File "C:\Users\mayal\OneDrive\מסמכים\JB\pyt\SQLITE PCT\trying\projectNumber1\env\Lib\site-packages\sqlalchemy\engine\default.py", line 700, in do_rollback
    dbapi_connection.rollback()
    ~~~~~~~~~~~~~~~~~~~~~~~~~^^
psycopg2.OperationalError: SSL connection has been closed unexpectedly

2025-02-16 19:48:11,530 - my log - INFO - Fetched all active loans
2025-02-16 19:48:11,543 - my log - INFO - Fetched 0 customers based on search filters
2025-02-16 19:48:11,650 - my log - INFO - Fetched all late loans
2025-02-16 19:49:45,205 - my log - INFO - Login endpoint accessed
2025-02-16 19:49:45,205 - my log - ERROR - Error during login: 415 Unsupported Media Type: Did not attempt to load JSON data because the request Content-Type was not 'application/json'.
2025-02-16 19:49:47,871 - my log - INFO - Login endpoint accessed
2025-02-16 19:49:47,871 - my log - ERROR - Error during login: 415 Unsupported Media Type: Did not attempt to load JSON data because the request Content-Type was not 'application/json'.
2025-02-16 19:50:16,449 - my log - INFO - Login endpoint accessed
2025-02-16 19:50:16,750 - my log - ERROR - Error during login: argument 'password': 'int' object cannot be converted to 'PyBytes'
2025-02-16 19:50:23,251 - my log - INFO - Login endpoint accessed
2025-02-16 19:50:24,777 - my log - INFO - Login successful for username: maya
2025-02-16 19:53:09,902 - my log - INFO - Fetched all late loans
2025-02-16 19:53:10,284 - my log - INFO - Fetched 0 customers based on search filters
2025-02-16 19:53:10,286 - my log - INFO - Fetched all active loans
2025-02-16 19:53:11,666 - sqlalchemy.pool.impl.QueuePool - ERROR - Exception during reset or similar
Traceback (most recent call last):
  File "C:\Users\mayal\OneDrive\מסמכים\JB\pyt\SQLITE PCT\trying\projectNumber1\env\Lib\site-packages\sqlalchemy\pool\base.py", line 986, in _finalize_fairy
    fairy._reset(
    ~~~~~~~~~~~~^
        pool,
        ^^^^^
    ...<2 lines>...
        asyncio_safe=can_manipulate_connection,
        ^^^^^^^^^^^^^^^^^^^^^^^^^^^^^^^^^^^^^^^
    )
    ^
  File "C:\Users\mayal\OneDrive\מסמכים\JB\pyt\SQLITE PCT\trying\projectNumber1\env\Lib\site-packages\sqlalchemy\pool\base.py", line 1432, in _reset
    pool._dialect.do_rollback(self)
    ~~~~~~~~~~~~~~~~~~~~~~~~~^^^^^^
  File "C:\Users\mayal\OneDrive\מסמכים\JB\pyt\SQLITE PCT\trying\projectNumber1\env\Lib\site-packages\sqlalchemy\engine\default.py", line 700, in do_rollback
    dbapi_connection.rollback()
    ~~~~~~~~~~~~~~~~~~~~~~~~~^^
psycopg2.OperationalError: SSL connection has been closed unexpectedly

2025-02-16 19:53:11,671 - sqlalchemy.pool.impl.QueuePool - ERROR - Exception during reset or similar
Traceback (most recent call last):
  File "C:\Users\mayal\OneDrive\מסמכים\JB\pyt\SQLITE PCT\trying\projectNumber1\env\Lib\site-packages\sqlalchemy\pool\base.py", line 986, in _finalize_fairy
    fairy._reset(
    ~~~~~~~~~~~~^
        pool,
        ^^^^^
    ...<2 lines>...
        asyncio_safe=can_manipulate_connection,
        ^^^^^^^^^^^^^^^^^^^^^^^^^^^^^^^^^^^^^^^
    )
    ^
  File "C:\Users\mayal\OneDrive\מסמכים\JB\pyt\SQLITE PCT\trying\projectNumber1\env\Lib\site-packages\sqlalchemy\pool\base.py", line 1432, in _reset
    pool._dialect.do_rollback(self)
    ~~~~~~~~~~~~~~~~~~~~~~~~~^^^^^^
  File "C:\Users\mayal\OneDrive\מסמכים\JB\pyt\SQLITE PCT\trying\projectNumber1\env\Lib\site-packages\sqlalchemy\engine\default.py", line 700, in do_rollback
    dbapi_connection.rollback()
    ~~~~~~~~~~~~~~~~~~~~~~~~~^^
psycopg2.OperationalError: SSL connection has been closed unexpectedly

2025-02-16 19:53:11,673 - sqlalchemy.pool.impl.QueuePool - ERROR - Exception during reset or similar
Traceback (most recent call last):
  File "C:\Users\mayal\OneDrive\מסמכים\JB\pyt\SQLITE PCT\trying\projectNumber1\env\Lib\site-packages\sqlalchemy\pool\base.py", line 986, in _finalize_fairy
    fairy._reset(
    ~~~~~~~~~~~~^
        pool,
        ^^^^^
    ...<2 lines>...
        asyncio_safe=can_manipulate_connection,
        ^^^^^^^^^^^^^^^^^^^^^^^^^^^^^^^^^^^^^^^
    )
    ^
  File "C:\Users\mayal\OneDrive\מסמכים\JB\pyt\SQLITE PCT\trying\projectNumber1\env\Lib\site-packages\sqlalchemy\pool\base.py", line 1432, in _reset
    pool._dialect.do_rollback(self)
    ~~~~~~~~~~~~~~~~~~~~~~~~~^^^^^^
  File "C:\Users\mayal\OneDrive\מסמכים\JB\pyt\SQLITE PCT\trying\projectNumber1\env\Lib\site-packages\sqlalchemy\engine\default.py", line 700, in do_rollback
    dbapi_connection.rollback()
    ~~~~~~~~~~~~~~~~~~~~~~~~~^^
psycopg2.OperationalError: SSL connection has been closed unexpectedly

2025-02-16 19:58:10,815 - my log - INFO - Fetched all late loans
2025-02-16 19:58:10,816 - my log - INFO - Fetched all active loans
2025-02-16 19:58:10,856 - my log - INFO - Fetched 0 customers based on search filters
2025-02-16 19:58:18,339 - my log - INFO - Fetched 0 customers based on search filters
2025-02-16 19:58:18,358 - my log - INFO - Fetched all active loans
2025-02-16 19:58:18,369 - my log - INFO - Fetched all late loans
2025-02-16 19:58:44,044 - my log - INFO - Fetched 0 customers based on search filters
2025-02-16 19:58:44,045 - my log - INFO - Fetched all late loans
2025-02-16 19:58:44,047 - my log - INFO - Fetched all active loans
2025-02-16 20:02:43,923 - my log - INFO - Fetched 0 customers based on search filters
2025-02-16 20:02:43,929 - my log - INFO - Fetched all active loans
2025-02-16 20:02:43,930 - my log - INFO - Fetched all late loans
2025-02-16 20:03:23,375 - my log - INFO - Fetched 0 customers based on search filters
2025-02-16 20:03:24,379 - my log - INFO - Fetched all active loans
2025-02-16 20:03:24,380 - my log - INFO - Fetched all late loans
2025-02-16 20:03:27,444 - my log - INFO - Fetched all active loans
2025-02-16 20:03:27,543 - my log - INFO - Fetched 0 customers based on search filters
2025-02-16 20:03:27,559 - my log - INFO - Fetched all late loans
2025-02-16 20:06:54,621 - my log - INFO - Signup endpoint accessed
2025-02-16 20:06:55,818 - sqlalchemy.pool.impl.QueuePool - ERROR - Exception during reset or similar
Traceback (most recent call last):
  File "C:\Users\mayal\OneDrive\מסמכים\JB\pyt\SQLITE PCT\trying\projectNumber1\env\Lib\site-packages\sqlalchemy\pool\base.py", line 986, in _finalize_fairy
    fairy._reset(
    ~~~~~~~~~~~~^
        pool,
        ^^^^^
    ...<2 lines>...
        asyncio_safe=can_manipulate_connection,
        ^^^^^^^^^^^^^^^^^^^^^^^^^^^^^^^^^^^^^^^
    )
    ^
  File "C:\Users\mayal\OneDrive\מסמכים\JB\pyt\SQLITE PCT\trying\projectNumber1\env\Lib\site-packages\sqlalchemy\pool\base.py", line 1432, in _reset
    pool._dialect.do_rollback(self)
    ~~~~~~~~~~~~~~~~~~~~~~~~~^^^^^^
  File "C:\Users\mayal\OneDrive\מסמכים\JB\pyt\SQLITE PCT\trying\projectNumber1\env\Lib\site-packages\sqlalchemy\engine\default.py", line 700, in do_rollback
    dbapi_connection.rollback()
    ~~~~~~~~~~~~~~~~~~~~~~~~~^^
psycopg2.OperationalError: SSL connection has been closed unexpectedly

2025-02-16 20:06:55,821 - sqlalchemy.pool.impl.QueuePool - ERROR - Exception during reset or similar
Traceback (most recent call last):
  File "C:\Users\mayal\OneDrive\מסמכים\JB\pyt\SQLITE PCT\trying\projectNumber1\env\Lib\site-packages\sqlalchemy\pool\base.py", line 986, in _finalize_fairy
    fairy._reset(
    ~~~~~~~~~~~~^
        pool,
        ^^^^^
    ...<2 lines>...
        asyncio_safe=can_manipulate_connection,
        ^^^^^^^^^^^^^^^^^^^^^^^^^^^^^^^^^^^^^^^
    )
    ^
  File "C:\Users\mayal\OneDrive\מסמכים\JB\pyt\SQLITE PCT\trying\projectNumber1\env\Lib\site-packages\sqlalchemy\pool\base.py", line 1432, in _reset
    pool._dialect.do_rollback(self)
    ~~~~~~~~~~~~~~~~~~~~~~~~~^^^^^^
  File "C:\Users\mayal\OneDrive\מסמכים\JB\pyt\SQLITE PCT\trying\projectNumber1\env\Lib\site-packages\sqlalchemy\engine\default.py", line 700, in do_rollback
    dbapi_connection.rollback()
    ~~~~~~~~~~~~~~~~~~~~~~~~~^^
psycopg2.OperationalError: SSL connection has been closed unexpectedly

2025-02-16 20:06:57,465 - my log - INFO - Signup endpoint accessed
2025-02-16 20:06:58,830 - my log - WARNING - Email already registered: shlomi@gmail.com
2025-02-16 20:06:59,958 - my log - INFO - New customer added: <Customer(id=2, firstName=Shlomi, lastName=Judom, city=Ohio, age=23, birthDate=2001-02-17, active=True, phoneNumber=058-4943394, email=shlomi@gmail.com, role=user, username=shlomi, password=$2b$12$ST/aFh4ZH5CEtmY5poMpieMrQxkhGDlIU4Cz4ZOEwSpleMVpYyjbG)>
2025-02-16 20:07:11,176 - my log - INFO - Login endpoint accessed
2025-02-16 20:07:11,769 - my log - INFO - Login successful for username: shlomi
2025-02-16 20:07:11,781 - my log - INFO - User dashboard accessed by username: shlomi
2025-02-16 20:07:12,083 - my log - INFO - User dashboard access granted for username: shlomi
2025-02-16 20:07:12,788 - my log - INFO - findCustomersBooks accessed by username: shlomi
2025-02-16 20:07:13,215 - my log - INFO - Loaned books retrieved for username: shlomi
2025-02-16 20:07:15,584 - my log - INFO - Guest watch list accessed
2025-02-16 20:12:54,597 - my log - INFO - Signup endpoint accessed
2025-02-16 20:12:56,258 - my log - INFO - New customer added: <Customer(id=3, firstName=Joseph, lastName=Judom, city=Ohio, age=18, birthDate=2006-07-22, active=True, phoneNumber=054-4943394, email=joseph@gmail.com, role=user, username=joseph, password=$2b$12$z0DkhM9650XKZ2YTnWJpg.pyf89Mm3QqY9CK1Hvin7iOg43MJNrp2)>
2025-02-16 20:14:36,093 - my log - INFO - Login endpoint accessed
2025-02-16 20:14:36,636 - my log - INFO - Login successful for username: maya
2025-02-16 20:14:36,647 - my log - INFO - Manager dashboard accessed by username: maya
2025-02-16 20:14:36,947 - my log - INFO - Manager dashboard access granted for username: maya
2025-02-16 20:14:37,124 - sqlalchemy.pool.impl.QueuePool - ERROR - Exception during reset or similar
Traceback (most recent call last):
  File "C:\Users\mayal\OneDrive\מסמכים\JB\pyt\SQLITE PCT\trying\projectNumber1\env\Lib\site-packages\sqlalchemy\pool\base.py", line 986, in _finalize_fairy
    fairy._reset(
    ~~~~~~~~~~~~^
        pool,
        ^^^^^
    ...<2 lines>...
        asyncio_safe=can_manipulate_connection,
        ^^^^^^^^^^^^^^^^^^^^^^^^^^^^^^^^^^^^^^^
    )
    ^
  File "C:\Users\mayal\OneDrive\מסמכים\JB\pyt\SQLITE PCT\trying\projectNumber1\env\Lib\site-packages\sqlalchemy\pool\base.py", line 1432, in _reset
    pool._dialect.do_rollback(self)
    ~~~~~~~~~~~~~~~~~~~~~~~~~^^^^^^
  File "C:\Users\mayal\OneDrive\מסמכים\JB\pyt\SQLITE PCT\trying\projectNumber1\env\Lib\site-packages\sqlalchemy\engine\default.py", line 700, in do_rollback
    dbapi_connection.rollback()
    ~~~~~~~~~~~~~~~~~~~~~~~~~^^
psycopg2.OperationalError: SSL connection has been closed unexpectedly

2025-02-16 20:14:37,127 - sqlalchemy.pool.impl.QueuePool - ERROR - Exception during reset or similar
Traceback (most recent call last):
  File "C:\Users\mayal\OneDrive\מסמכים\JB\pyt\SQLITE PCT\trying\projectNumber1\env\Lib\site-packages\sqlalchemy\pool\base.py", line 986, in _finalize_fairy
    fairy._reset(
    ~~~~~~~~~~~~^
        pool,
        ^^^^^
    ...<2 lines>...
        asyncio_safe=can_manipulate_connection,
        ^^^^^^^^^^^^^^^^^^^^^^^^^^^^^^^^^^^^^^^
    )
    ^
  File "C:\Users\mayal\OneDrive\מסמכים\JB\pyt\SQLITE PCT\trying\projectNumber1\env\Lib\site-packages\sqlalchemy\pool\base.py", line 1432, in _reset
    pool._dialect.do_rollback(self)
    ~~~~~~~~~~~~~~~~~~~~~~~~~^^^^^^
  File "C:\Users\mayal\OneDrive\מסמכים\JB\pyt\SQLITE PCT\trying\projectNumber1\env\Lib\site-packages\sqlalchemy\engine\default.py", line 700, in do_rollback
    dbapi_connection.rollback()
    ~~~~~~~~~~~~~~~~~~~~~~~~~^^
psycopg2.OperationalError: SSL connection has been closed unexpectedly

2025-02-16 20:14:37,128 - sqlalchemy.pool.impl.QueuePool - ERROR - Exception during reset or similar
Traceback (most recent call last):
  File "C:\Users\mayal\OneDrive\מסמכים\JB\pyt\SQLITE PCT\trying\projectNumber1\env\Lib\site-packages\sqlalchemy\pool\base.py", line 986, in _finalize_fairy
    fairy._reset(
    ~~~~~~~~~~~~^
        pool,
        ^^^^^
    ...<2 lines>...
        asyncio_safe=can_manipulate_connection,
        ^^^^^^^^^^^^^^^^^^^^^^^^^^^^^^^^^^^^^^^
    )
    ^
  File "C:\Users\mayal\OneDrive\מסמכים\JB\pyt\SQLITE PCT\trying\projectNumber1\env\Lib\site-packages\sqlalchemy\pool\base.py", line 1432, in _reset
    pool._dialect.do_rollback(self)
    ~~~~~~~~~~~~~~~~~~~~~~~~~^^^^^^
  File "C:\Users\mayal\OneDrive\מסמכים\JB\pyt\SQLITE PCT\trying\projectNumber1\env\Lib\site-packages\sqlalchemy\engine\default.py", line 700, in do_rollback
    dbapi_connection.rollback()
    ~~~~~~~~~~~~~~~~~~~~~~~~~^^
psycopg2.OperationalError: SSL connection has been closed unexpectedly

2025-02-16 20:14:37,129 - sqlalchemy.pool.impl.QueuePool - ERROR - Exception during reset or similar
Traceback (most recent call last):
  File "C:\Users\mayal\OneDrive\מסמכים\JB\pyt\SQLITE PCT\trying\projectNumber1\env\Lib\site-packages\sqlalchemy\pool\base.py", line 986, in _finalize_fairy
    fairy._reset(
    ~~~~~~~~~~~~^
        pool,
        ^^^^^
    ...<2 lines>...
        asyncio_safe=can_manipulate_connection,
        ^^^^^^^^^^^^^^^^^^^^^^^^^^^^^^^^^^^^^^^
    )
    ^
  File "C:\Users\mayal\OneDrive\מסמכים\JB\pyt\SQLITE PCT\trying\projectNumber1\env\Lib\site-packages\sqlalchemy\pool\base.py", line 1432, in _reset
    pool._dialect.do_rollback(self)
    ~~~~~~~~~~~~~~~~~~~~~~~~~^^^^^^
  File "C:\Users\mayal\OneDrive\מסמכים\JB\pyt\SQLITE PCT\trying\projectNumber1\env\Lib\site-packages\sqlalchemy\engine\default.py", line 700, in do_rollback
    dbapi_connection.rollback()
    ~~~~~~~~~~~~~~~~~~~~~~~~~^^
psycopg2.OperationalError: SSL connection has been closed unexpectedly

2025-02-16 20:14:37,130 - sqlalchemy.pool.impl.QueuePool - ERROR - Exception during reset or similar
Traceback (most recent call last):
  File "C:\Users\mayal\OneDrive\מסמכים\JB\pyt\SQLITE PCT\trying\projectNumber1\env\Lib\site-packages\sqlalchemy\pool\base.py", line 986, in _finalize_fairy
    fairy._reset(
    ~~~~~~~~~~~~^
        pool,
        ^^^^^
    ...<2 lines>...
        asyncio_safe=can_manipulate_connection,
        ^^^^^^^^^^^^^^^^^^^^^^^^^^^^^^^^^^^^^^^
    )
    ^
  File "C:\Users\mayal\OneDrive\מסמכים\JB\pyt\SQLITE PCT\trying\projectNumber1\env\Lib\site-packages\sqlalchemy\pool\base.py", line 1432, in _reset
    pool._dialect.do_rollback(self)
    ~~~~~~~~~~~~~~~~~~~~~~~~~^^^^^^
  File "C:\Users\mayal\OneDrive\מסמכים\JB\pyt\SQLITE PCT\trying\projectNumber1\env\Lib\site-packages\sqlalchemy\engine\default.py", line 700, in do_rollback
    dbapi_connection.rollback()
    ~~~~~~~~~~~~~~~~~~~~~~~~~^^
psycopg2.OperationalError: SSL connection has been closed unexpectedly

2025-02-16 20:14:37,414 - my log - INFO - Fetched 2 customers based on search filters
2025-02-16 20:14:38,317 - my log - INFO - Fetched all active loans
2025-02-16 20:14:38,806 - my log - INFO - Fetched all late loans
2025-02-16 20:15:50,435 - my log - INFO - Fetched all late loans
2025-02-16 20:15:50,535 - my log - INFO - Fetched all active loans
2025-02-16 20:15:50,542 - my log - INFO - Fetched 2 customers based on search filters
2025-02-16 20:15:50,950 - my log - INFO - Fetched all active loans
2025-02-16 20:15:50,985 - my log - INFO - Fetched 2 customers based on search filters
2025-02-16 20:15:51,840 - my log - INFO - Fetched all late loans
2025-02-16 20:16:52,950 - my log - INFO - Fetched all active loans
2025-02-16 20:16:52,961 - my log - INFO - Fetched all late loans
2025-02-16 20:16:52,966 - my log - INFO - Fetched 2 customers based on search filters
2025-02-16 20:16:54,312 - my log - INFO - Fetched all late loans
2025-02-16 20:16:54,315 - my log - INFO - Fetched all active loans
2025-02-16 20:16:54,343 - my log - INFO - Fetched 2 customers based on search filters
2025-02-16 20:16:54,487 - my log - INFO - Fetched 2 customers based on search filters
2025-02-16 20:16:54,629 - my log - INFO - Fetched all active loans
2025-02-16 20:16:55,567 - my log - INFO - Fetched all late loans
2025-02-16 20:17:02,344 - my log - INFO - Fetched all active loans
2025-02-16 20:17:02,352 - my log - INFO - Fetched 2 customers based on search filters
2025-02-16 20:17:02,353 - my log - INFO - Fetched all late loans
2025-02-16 20:17:05,459 - my log - INFO - Fetched 2 customers based on search filters
2025-02-16 20:17:05,476 - my log - INFO - Fetched all late loans
2025-02-16 20:17:05,477 - my log - INFO - Fetched all active loans
2025-02-16 20:17:08,130 - my log - INFO - Fetched 2 customers based on search filters
2025-02-16 20:17:08,131 - my log - INFO - Fetched all active loans
2025-02-16 20:17:08,131 - my log - INFO - Fetched all late loans
2025-02-16 20:17:09,354 - my log - INFO - Fetched all active loans
2025-02-16 20:17:09,384 - my log - INFO - Fetched 2 customers based on search filters
2025-02-16 20:17:38,066 - my log - ERROR - Error in books endpoint: QueuePool limit of size 10 overflow 20 reached, connection timed out, timeout 30.00 (Background on this error at: https://sqlalche.me/e/20/3o7r)
2025-02-16 20:17:38,083 - my log - ERROR - Error in lateLoans endpoint: QueuePool limit of size 10 overflow 20 reached, connection timed out, timeout 30.00 (Background on this error at: https://sqlalche.me/e/20/3o7r)
2025-02-16 20:17:43,836 - my log - INFO - Fetched 2 customers based on search filters
2025-02-16 20:17:43,968 - my log - INFO - Fetched all active loans
2025-02-16 20:17:44,116 - my log - INFO - Fetched all late loans
2025-02-16 20:17:44,411 - my log - INFO - Fetched all active loans
2025-02-16 20:17:44,552 - my log - INFO - Fetched all late loans
2025-02-16 20:17:45,814 - my log - INFO - Fetched 2 customers based on search filters
2025-02-16 20:18:04,393 - my log - INFO - Fetched all active loans
2025-02-16 20:18:04,408 - my log - INFO - Fetched all late loans
2025-02-16 20:18:04,409 - my log - INFO - Fetched 2 customers based on search filters
2025-02-16 20:21:34,706 - my log - INFO - Login endpoint accessed
2025-02-16 20:21:41,940 - my log - INFO - Login successful for username: maya
2025-02-16 20:21:41,952 - my log - INFO - Manager dashboard accessed by username: maya
2025-02-16 20:21:42,231 - my log - INFO - Manager dashboard access granted for username: maya
2025-02-16 20:21:42,716 - my log - INFO - Fetched all late loans
2025-02-16 20:21:42,719 - my log - INFO - Fetched all active loans
2025-02-16 20:21:42,720 - my log - INFO - Fetched 2 customers based on search filters
2025-02-16 20:21:42,724 - my log - INFO - Login endpoint accessed
2025-02-16 20:21:43,263 - my log - INFO - Login successful for username: maya
2025-02-16 20:22:03,939 - my log - INFO - Fetched 2 customers based on search filters
2025-02-16 20:22:33,646 - my log - ERROR - Error in lateLoans endpoint: QueuePool limit of size 10 overflow 20 reached, connection timed out, timeout 30.00 (Background on this error at: https://sqlalche.me/e/20/3o7r)
2025-02-16 20:22:33,646 - my log - ERROR - Error in loans endpoint: QueuePool limit of size 10 overflow 20 reached, connection timed out, timeout 30.00 (Background on this error at: https://sqlalche.me/e/20/3o7r)
2025-02-16 20:31:04,409 - sqlalchemy.pool.impl.QueuePool - ERROR - Exception during reset or similar
Traceback (most recent call last):
  File "C:\Users\mayal\OneDrive\מסמכים\JB\pyt\SQLITE PCT\trying\projectNumber1\env\Lib\site-packages\sqlalchemy\pool\base.py", line 986, in _finalize_fairy
    fairy._reset(
    ~~~~~~~~~~~~^
        pool,
        ^^^^^
    ...<2 lines>...
        asyncio_safe=can_manipulate_connection,
        ^^^^^^^^^^^^^^^^^^^^^^^^^^^^^^^^^^^^^^^
    )
    ^
  File "C:\Users\mayal\OneDrive\מסמכים\JB\pyt\SQLITE PCT\trying\projectNumber1\env\Lib\site-packages\sqlalchemy\pool\base.py", line 1432, in _reset
    pool._dialect.do_rollback(self)
    ~~~~~~~~~~~~~~~~~~~~~~~~~^^^^^^
  File "C:\Users\mayal\OneDrive\מסמכים\JB\pyt\SQLITE PCT\trying\projectNumber1\env\Lib\site-packages\sqlalchemy\engine\default.py", line 700, in do_rollback
    dbapi_connection.rollback()
    ~~~~~~~~~~~~~~~~~~~~~~~~~^^
psycopg2.OperationalError: SSL connection has been closed unexpectedly

2025-02-16 20:31:04,411 - sqlalchemy.pool.impl.QueuePool - ERROR - Exception during reset or similar
Traceback (most recent call last):
  File "C:\Users\mayal\OneDrive\מסמכים\JB\pyt\SQLITE PCT\trying\projectNumber1\env\Lib\site-packages\sqlalchemy\pool\base.py", line 986, in _finalize_fairy
    fairy._reset(
    ~~~~~~~~~~~~^
        pool,
        ^^^^^
    ...<2 lines>...
        asyncio_safe=can_manipulate_connection,
        ^^^^^^^^^^^^^^^^^^^^^^^^^^^^^^^^^^^^^^^
    )
    ^
  File "C:\Users\mayal\OneDrive\מסמכים\JB\pyt\SQLITE PCT\trying\projectNumber1\env\Lib\site-packages\sqlalchemy\pool\base.py", line 1432, in _reset
    pool._dialect.do_rollback(self)
    ~~~~~~~~~~~~~~~~~~~~~~~~~^^^^^^
  File "C:\Users\mayal\OneDrive\מסמכים\JB\pyt\SQLITE PCT\trying\projectNumber1\env\Lib\site-packages\sqlalchemy\engine\default.py", line 700, in do_rollback
    dbapi_connection.rollback()
    ~~~~~~~~~~~~~~~~~~~~~~~~~^^
psycopg2.OperationalError: SSL connection has been closed unexpectedly

2025-02-16 20:31:04,413 - sqlalchemy.pool.impl.QueuePool - ERROR - Exception during reset or similar
Traceback (most recent call last):
  File "C:\Users\mayal\OneDrive\מסמכים\JB\pyt\SQLITE PCT\trying\projectNumber1\env\Lib\site-packages\sqlalchemy\pool\base.py", line 986, in _finalize_fairy
    fairy._reset(
    ~~~~~~~~~~~~^
        pool,
        ^^^^^
    ...<2 lines>...
        asyncio_safe=can_manipulate_connection,
        ^^^^^^^^^^^^^^^^^^^^^^^^^^^^^^^^^^^^^^^
    )
    ^
  File "C:\Users\mayal\OneDrive\מסמכים\JB\pyt\SQLITE PCT\trying\projectNumber1\env\Lib\site-packages\sqlalchemy\pool\base.py", line 1432, in _reset
    pool._dialect.do_rollback(self)
    ~~~~~~~~~~~~~~~~~~~~~~~~~^^^^^^
  File "C:\Users\mayal\OneDrive\מסמכים\JB\pyt\SQLITE PCT\trying\projectNumber1\env\Lib\site-packages\sqlalchemy\engine\default.py", line 700, in do_rollback
    dbapi_connection.rollback()
    ~~~~~~~~~~~~~~~~~~~~~~~~~^^
psycopg2.OperationalError: SSL connection has been closed unexpectedly

2025-02-16 20:31:04,415 - sqlalchemy.pool.impl.QueuePool - ERROR - Exception during reset or similar
Traceback (most recent call last):
  File "C:\Users\mayal\OneDrive\מסמכים\JB\pyt\SQLITE PCT\trying\projectNumber1\env\Lib\site-packages\sqlalchemy\pool\base.py", line 986, in _finalize_fairy
    fairy._reset(
    ~~~~~~~~~~~~^
        pool,
        ^^^^^
    ...<2 lines>...
        asyncio_safe=can_manipulate_connection,
        ^^^^^^^^^^^^^^^^^^^^^^^^^^^^^^^^^^^^^^^
    )
    ^
  File "C:\Users\mayal\OneDrive\מסמכים\JB\pyt\SQLITE PCT\trying\projectNumber1\env\Lib\site-packages\sqlalchemy\pool\base.py", line 1432, in _reset
    pool._dialect.do_rollback(self)
    ~~~~~~~~~~~~~~~~~~~~~~~~~^^^^^^
  File "C:\Users\mayal\OneDrive\מסמכים\JB\pyt\SQLITE PCT\trying\projectNumber1\env\Lib\site-packages\sqlalchemy\engine\default.py", line 700, in do_rollback
    dbapi_connection.rollback()
    ~~~~~~~~~~~~~~~~~~~~~~~~~^^
psycopg2.OperationalError: SSL connection has been closed unexpectedly

2025-02-16 20:31:04,417 - sqlalchemy.pool.impl.QueuePool - ERROR - Exception during reset or similar
Traceback (most recent call last):
  File "C:\Users\mayal\OneDrive\מסמכים\JB\pyt\SQLITE PCT\trying\projectNumber1\env\Lib\site-packages\sqlalchemy\pool\base.py", line 986, in _finalize_fairy
    fairy._reset(
    ~~~~~~~~~~~~^
        pool,
        ^^^^^
    ...<2 lines>...
        asyncio_safe=can_manipulate_connection,
        ^^^^^^^^^^^^^^^^^^^^^^^^^^^^^^^^^^^^^^^
    )
    ^
  File "C:\Users\mayal\OneDrive\מסמכים\JB\pyt\SQLITE PCT\trying\projectNumber1\env\Lib\site-packages\sqlalchemy\pool\base.py", line 1432, in _reset
    pool._dialect.do_rollback(self)
    ~~~~~~~~~~~~~~~~~~~~~~~~~^^^^^^
  File "C:\Users\mayal\OneDrive\מסמכים\JB\pyt\SQLITE PCT\trying\projectNumber1\env\Lib\site-packages\sqlalchemy\engine\default.py", line 700, in do_rollback
    dbapi_connection.rollback()
    ~~~~~~~~~~~~~~~~~~~~~~~~~^^
psycopg2.OperationalError: SSL connection has been closed unexpectedly

2025-02-16 20:31:04,419 - sqlalchemy.pool.impl.QueuePool - ERROR - Exception during reset or similar
Traceback (most recent call last):
  File "C:\Users\mayal\OneDrive\מסמכים\JB\pyt\SQLITE PCT\trying\projectNumber1\env\Lib\site-packages\sqlalchemy\pool\base.py", line 986, in _finalize_fairy
    fairy._reset(
    ~~~~~~~~~~~~^
        pool,
        ^^^^^
    ...<2 lines>...
        asyncio_safe=can_manipulate_connection,
        ^^^^^^^^^^^^^^^^^^^^^^^^^^^^^^^^^^^^^^^
    )
    ^
  File "C:\Users\mayal\OneDrive\מסמכים\JB\pyt\SQLITE PCT\trying\projectNumber1\env\Lib\site-packages\sqlalchemy\pool\base.py", line 1432, in _reset
    pool._dialect.do_rollback(self)
    ~~~~~~~~~~~~~~~~~~~~~~~~~^^^^^^
  File "C:\Users\mayal\OneDrive\מסמכים\JB\pyt\SQLITE PCT\trying\projectNumber1\env\Lib\site-packages\sqlalchemy\engine\default.py", line 700, in do_rollback
    dbapi_connection.rollback()
    ~~~~~~~~~~~~~~~~~~~~~~~~~^^
psycopg2.OperationalError: SSL connection has been closed unexpectedly

2025-02-16 20:31:04,420 - sqlalchemy.pool.impl.QueuePool - ERROR - Exception during reset or similar
Traceback (most recent call last):
  File "C:\Users\mayal\OneDrive\מסמכים\JB\pyt\SQLITE PCT\trying\projectNumber1\env\Lib\site-packages\sqlalchemy\pool\base.py", line 986, in _finalize_fairy
    fairy._reset(
    ~~~~~~~~~~~~^
        pool,
        ^^^^^
    ...<2 lines>...
        asyncio_safe=can_manipulate_connection,
        ^^^^^^^^^^^^^^^^^^^^^^^^^^^^^^^^^^^^^^^
    )
    ^
  File "C:\Users\mayal\OneDrive\מסמכים\JB\pyt\SQLITE PCT\trying\projectNumber1\env\Lib\site-packages\sqlalchemy\pool\base.py", line 1432, in _reset
    pool._dialect.do_rollback(self)
    ~~~~~~~~~~~~~~~~~~~~~~~~~^^^^^^
  File "C:\Users\mayal\OneDrive\מסמכים\JB\pyt\SQLITE PCT\trying\projectNumber1\env\Lib\site-packages\sqlalchemy\engine\default.py", line 700, in do_rollback
    dbapi_connection.rollback()
    ~~~~~~~~~~~~~~~~~~~~~~~~~^^
psycopg2.OperationalError: SSL connection has been closed unexpectedly

2025-02-16 20:31:04,423 - sqlalchemy.pool.impl.QueuePool - ERROR - Exception during reset or similar
Traceback (most recent call last):
  File "C:\Users\mayal\OneDrive\מסמכים\JB\pyt\SQLITE PCT\trying\projectNumber1\env\Lib\site-packages\sqlalchemy\pool\base.py", line 986, in _finalize_fairy
    fairy._reset(
    ~~~~~~~~~~~~^
        pool,
        ^^^^^
    ...<2 lines>...
        asyncio_safe=can_manipulate_connection,
        ^^^^^^^^^^^^^^^^^^^^^^^^^^^^^^^^^^^^^^^
    )
    ^
  File "C:\Users\mayal\OneDrive\מסמכים\JB\pyt\SQLITE PCT\trying\projectNumber1\env\Lib\site-packages\sqlalchemy\pool\base.py", line 1432, in _reset
    pool._dialect.do_rollback(self)
    ~~~~~~~~~~~~~~~~~~~~~~~~~^^^^^^
  File "C:\Users\mayal\OneDrive\מסמכים\JB\pyt\SQLITE PCT\trying\projectNumber1\env\Lib\site-packages\sqlalchemy\engine\default.py", line 700, in do_rollback
    dbapi_connection.rollback()
    ~~~~~~~~~~~~~~~~~~~~~~~~~^^
psycopg2.OperationalError: SSL connection has been closed unexpectedly

2025-02-16 20:31:04,425 - sqlalchemy.pool.impl.QueuePool - ERROR - Exception during reset or similar
Traceback (most recent call last):
  File "C:\Users\mayal\OneDrive\מסמכים\JB\pyt\SQLITE PCT\trying\projectNumber1\env\Lib\site-packages\sqlalchemy\pool\base.py", line 986, in _finalize_fairy
    fairy._reset(
    ~~~~~~~~~~~~^
        pool,
        ^^^^^
    ...<2 lines>...
        asyncio_safe=can_manipulate_connection,
        ^^^^^^^^^^^^^^^^^^^^^^^^^^^^^^^^^^^^^^^
    )
    ^
  File "C:\Users\mayal\OneDrive\מסמכים\JB\pyt\SQLITE PCT\trying\projectNumber1\env\Lib\site-packages\sqlalchemy\pool\base.py", line 1432, in _reset
    pool._dialect.do_rollback(self)
    ~~~~~~~~~~~~~~~~~~~~~~~~~^^^^^^
  File "C:\Users\mayal\OneDrive\מסמכים\JB\pyt\SQLITE PCT\trying\projectNumber1\env\Lib\site-packages\sqlalchemy\engine\default.py", line 700, in do_rollback
    dbapi_connection.rollback()
    ~~~~~~~~~~~~~~~~~~~~~~~~~^^
psycopg2.OperationalError: SSL connection has been closed unexpectedly

2025-02-16 20:31:04,427 - sqlalchemy.pool.impl.QueuePool - ERROR - Exception during reset or similar
Traceback (most recent call last):
  File "C:\Users\mayal\OneDrive\מסמכים\JB\pyt\SQLITE PCT\trying\projectNumber1\env\Lib\site-packages\sqlalchemy\pool\base.py", line 986, in _finalize_fairy
    fairy._reset(
    ~~~~~~~~~~~~^
        pool,
        ^^^^^
    ...<2 lines>...
        asyncio_safe=can_manipulate_connection,
        ^^^^^^^^^^^^^^^^^^^^^^^^^^^^^^^^^^^^^^^
    )
    ^
  File "C:\Users\mayal\OneDrive\מסמכים\JB\pyt\SQLITE PCT\trying\projectNumber1\env\Lib\site-packages\sqlalchemy\pool\base.py", line 1432, in _reset
    pool._dialect.do_rollback(self)
    ~~~~~~~~~~~~~~~~~~~~~~~~~^^^^^^
  File "C:\Users\mayal\OneDrive\מסמכים\JB\pyt\SQLITE PCT\trying\projectNumber1\env\Lib\site-packages\sqlalchemy\engine\default.py", line 700, in do_rollback
    dbapi_connection.rollback()
    ~~~~~~~~~~~~~~~~~~~~~~~~~^^
psycopg2.OperationalError: SSL connection has been closed unexpectedly

2025-02-16 20:31:04,429 - sqlalchemy.pool.impl.QueuePool - ERROR - Exception during reset or similar
Traceback (most recent call last):
  File "C:\Users\mayal\OneDrive\מסמכים\JB\pyt\SQLITE PCT\trying\projectNumber1\env\Lib\site-packages\sqlalchemy\pool\base.py", line 986, in _finalize_fairy
    fairy._reset(
    ~~~~~~~~~~~~^
        pool,
        ^^^^^
    ...<2 lines>...
        asyncio_safe=can_manipulate_connection,
        ^^^^^^^^^^^^^^^^^^^^^^^^^^^^^^^^^^^^^^^
    )
    ^
  File "C:\Users\mayal\OneDrive\מסמכים\JB\pyt\SQLITE PCT\trying\projectNumber1\env\Lib\site-packages\sqlalchemy\pool\base.py", line 1432, in _reset
    pool._dialect.do_rollback(self)
    ~~~~~~~~~~~~~~~~~~~~~~~~~^^^^^^
  File "C:\Users\mayal\OneDrive\מסמכים\JB\pyt\SQLITE PCT\trying\projectNumber1\env\Lib\site-packages\sqlalchemy\engine\default.py", line 700, in do_rollback
    dbapi_connection.rollback()
    ~~~~~~~~~~~~~~~~~~~~~~~~~^^
psycopg2.OperationalError: SSL connection has been closed unexpectedly

2025-02-16 20:31:04,431 - sqlalchemy.pool.impl.QueuePool - ERROR - Exception during reset or similar
Traceback (most recent call last):
  File "C:\Users\mayal\OneDrive\מסמכים\JB\pyt\SQLITE PCT\trying\projectNumber1\env\Lib\site-packages\sqlalchemy\pool\base.py", line 986, in _finalize_fairy
    fairy._reset(
    ~~~~~~~~~~~~^
        pool,
        ^^^^^
    ...<2 lines>...
        asyncio_safe=can_manipulate_connection,
        ^^^^^^^^^^^^^^^^^^^^^^^^^^^^^^^^^^^^^^^
    )
    ^
  File "C:\Users\mayal\OneDrive\מסמכים\JB\pyt\SQLITE PCT\trying\projectNumber1\env\Lib\site-packages\sqlalchemy\pool\base.py", line 1432, in _reset
    pool._dialect.do_rollback(self)
    ~~~~~~~~~~~~~~~~~~~~~~~~~^^^^^^
  File "C:\Users\mayal\OneDrive\מסמכים\JB\pyt\SQLITE PCT\trying\projectNumber1\env\Lib\site-packages\sqlalchemy\engine\default.py", line 700, in do_rollback
    dbapi_connection.rollback()
    ~~~~~~~~~~~~~~~~~~~~~~~~~^^
psycopg2.OperationalError: SSL connection has been closed unexpectedly

2025-02-16 20:31:04,433 - sqlalchemy.pool.impl.QueuePool - ERROR - Exception during reset or similar
Traceback (most recent call last):
  File "C:\Users\mayal\OneDrive\מסמכים\JB\pyt\SQLITE PCT\trying\projectNumber1\env\Lib\site-packages\sqlalchemy\pool\base.py", line 986, in _finalize_fairy
    fairy._reset(
    ~~~~~~~~~~~~^
        pool,
        ^^^^^
    ...<2 lines>...
        asyncio_safe=can_manipulate_connection,
        ^^^^^^^^^^^^^^^^^^^^^^^^^^^^^^^^^^^^^^^
    )
    ^
  File "C:\Users\mayal\OneDrive\מסמכים\JB\pyt\SQLITE PCT\trying\projectNumber1\env\Lib\site-packages\sqlalchemy\pool\base.py", line 1432, in _reset
    pool._dialect.do_rollback(self)
    ~~~~~~~~~~~~~~~~~~~~~~~~~^^^^^^
  File "C:\Users\mayal\OneDrive\מסמכים\JB\pyt\SQLITE PCT\trying\projectNumber1\env\Lib\site-packages\sqlalchemy\engine\default.py", line 700, in do_rollback
    dbapi_connection.rollback()
    ~~~~~~~~~~~~~~~~~~~~~~~~~^^
psycopg2.OperationalError: SSL connection has been closed unexpectedly

2025-02-16 20:31:04,434 - sqlalchemy.pool.impl.QueuePool - ERROR - Exception during reset or similar
Traceback (most recent call last):
  File "C:\Users\mayal\OneDrive\מסמכים\JB\pyt\SQLITE PCT\trying\projectNumber1\env\Lib\site-packages\sqlalchemy\pool\base.py", line 986, in _finalize_fairy
    fairy._reset(
    ~~~~~~~~~~~~^
        pool,
        ^^^^^
    ...<2 lines>...
        asyncio_safe=can_manipulate_connection,
        ^^^^^^^^^^^^^^^^^^^^^^^^^^^^^^^^^^^^^^^
    )
    ^
  File "C:\Users\mayal\OneDrive\מסמכים\JB\pyt\SQLITE PCT\trying\projectNumber1\env\Lib\site-packages\sqlalchemy\pool\base.py", line 1432, in _reset
    pool._dialect.do_rollback(self)
    ~~~~~~~~~~~~~~~~~~~~~~~~~^^^^^^
  File "C:\Users\mayal\OneDrive\מסמכים\JB\pyt\SQLITE PCT\trying\projectNumber1\env\Lib\site-packages\sqlalchemy\engine\default.py", line 700, in do_rollback
    dbapi_connection.rollback()
    ~~~~~~~~~~~~~~~~~~~~~~~~~^^
psycopg2.OperationalError: SSL connection has been closed unexpectedly

2025-02-16 20:31:04,436 - sqlalchemy.pool.impl.QueuePool - ERROR - Exception during reset or similar
Traceback (most recent call last):
  File "C:\Users\mayal\OneDrive\מסמכים\JB\pyt\SQLITE PCT\trying\projectNumber1\env\Lib\site-packages\sqlalchemy\pool\base.py", line 986, in _finalize_fairy
    fairy._reset(
    ~~~~~~~~~~~~^
        pool,
        ^^^^^
    ...<2 lines>...
        asyncio_safe=can_manipulate_connection,
        ^^^^^^^^^^^^^^^^^^^^^^^^^^^^^^^^^^^^^^^
    )
    ^
  File "C:\Users\mayal\OneDrive\מסמכים\JB\pyt\SQLITE PCT\trying\projectNumber1\env\Lib\site-packages\sqlalchemy\pool\base.py", line 1432, in _reset
    pool._dialect.do_rollback(self)
    ~~~~~~~~~~~~~~~~~~~~~~~~~^^^^^^
  File "C:\Users\mayal\OneDrive\מסמכים\JB\pyt\SQLITE PCT\trying\projectNumber1\env\Lib\site-packages\sqlalchemy\engine\default.py", line 700, in do_rollback
    dbapi_connection.rollback()
    ~~~~~~~~~~~~~~~~~~~~~~~~~^^
psycopg2.OperationalError: SSL connection has been closed unexpectedly

2025-02-16 20:31:04,439 - sqlalchemy.pool.impl.QueuePool - ERROR - Exception during reset or similar
Traceback (most recent call last):
  File "C:\Users\mayal\OneDrive\מסמכים\JB\pyt\SQLITE PCT\trying\projectNumber1\env\Lib\site-packages\sqlalchemy\pool\base.py", line 986, in _finalize_fairy
    fairy._reset(
    ~~~~~~~~~~~~^
        pool,
        ^^^^^
    ...<2 lines>...
        asyncio_safe=can_manipulate_connection,
        ^^^^^^^^^^^^^^^^^^^^^^^^^^^^^^^^^^^^^^^
    )
    ^
  File "C:\Users\mayal\OneDrive\מסמכים\JB\pyt\SQLITE PCT\trying\projectNumber1\env\Lib\site-packages\sqlalchemy\pool\base.py", line 1432, in _reset
    pool._dialect.do_rollback(self)
    ~~~~~~~~~~~~~~~~~~~~~~~~~^^^^^^
  File "C:\Users\mayal\OneDrive\מסמכים\JB\pyt\SQLITE PCT\trying\projectNumber1\env\Lib\site-packages\sqlalchemy\engine\default.py", line 700, in do_rollback
    dbapi_connection.rollback()
    ~~~~~~~~~~~~~~~~~~~~~~~~~^^
psycopg2.OperationalError: SSL connection has been closed unexpectedly

2025-02-16 20:31:04,440 - sqlalchemy.pool.impl.QueuePool - ERROR - Exception during reset or similar
Traceback (most recent call last):
  File "C:\Users\mayal\OneDrive\מסמכים\JB\pyt\SQLITE PCT\trying\projectNumber1\env\Lib\site-packages\sqlalchemy\pool\base.py", line 986, in _finalize_fairy
    fairy._reset(
    ~~~~~~~~~~~~^
        pool,
        ^^^^^
    ...<2 lines>...
        asyncio_safe=can_manipulate_connection,
        ^^^^^^^^^^^^^^^^^^^^^^^^^^^^^^^^^^^^^^^
    )
    ^
  File "C:\Users\mayal\OneDrive\מסמכים\JB\pyt\SQLITE PCT\trying\projectNumber1\env\Lib\site-packages\sqlalchemy\pool\base.py", line 1432, in _reset
    pool._dialect.do_rollback(self)
    ~~~~~~~~~~~~~~~~~~~~~~~~~^^^^^^
  File "C:\Users\mayal\OneDrive\מסמכים\JB\pyt\SQLITE PCT\trying\projectNumber1\env\Lib\site-packages\sqlalchemy\engine\default.py", line 700, in do_rollback
    dbapi_connection.rollback()
    ~~~~~~~~~~~~~~~~~~~~~~~~~^^
psycopg2.OperationalError: SSL connection has been closed unexpectedly

2025-02-16 20:31:04,442 - sqlalchemy.pool.impl.QueuePool - ERROR - Exception during reset or similar
Traceback (most recent call last):
  File "C:\Users\mayal\OneDrive\מסמכים\JB\pyt\SQLITE PCT\trying\projectNumber1\env\Lib\site-packages\sqlalchemy\pool\base.py", line 986, in _finalize_fairy
    fairy._reset(
    ~~~~~~~~~~~~^
        pool,
        ^^^^^
    ...<2 lines>...
        asyncio_safe=can_manipulate_connection,
        ^^^^^^^^^^^^^^^^^^^^^^^^^^^^^^^^^^^^^^^
    )
    ^
  File "C:\Users\mayal\OneDrive\מסמכים\JB\pyt\SQLITE PCT\trying\projectNumber1\env\Lib\site-packages\sqlalchemy\pool\base.py", line 1432, in _reset
    pool._dialect.do_rollback(self)
    ~~~~~~~~~~~~~~~~~~~~~~~~~^^^^^^
  File "C:\Users\mayal\OneDrive\מסמכים\JB\pyt\SQLITE PCT\trying\projectNumber1\env\Lib\site-packages\sqlalchemy\engine\default.py", line 700, in do_rollback
    dbapi_connection.rollback()
    ~~~~~~~~~~~~~~~~~~~~~~~~~^^
psycopg2.OperationalError: SSL connection has been closed unexpectedly

2025-02-16 20:31:04,444 - sqlalchemy.pool.impl.QueuePool - ERROR - Exception during reset or similar
Traceback (most recent call last):
  File "C:\Users\mayal\OneDrive\מסמכים\JB\pyt\SQLITE PCT\trying\projectNumber1\env\Lib\site-packages\sqlalchemy\pool\base.py", line 986, in _finalize_fairy
    fairy._reset(
    ~~~~~~~~~~~~^
        pool,
        ^^^^^
    ...<2 lines>...
        asyncio_safe=can_manipulate_connection,
        ^^^^^^^^^^^^^^^^^^^^^^^^^^^^^^^^^^^^^^^
    )
    ^
  File "C:\Users\mayal\OneDrive\מסמכים\JB\pyt\SQLITE PCT\trying\projectNumber1\env\Lib\site-packages\sqlalchemy\pool\base.py", line 1432, in _reset
    pool._dialect.do_rollback(self)
    ~~~~~~~~~~~~~~~~~~~~~~~~~^^^^^^
  File "C:\Users\mayal\OneDrive\מסמכים\JB\pyt\SQLITE PCT\trying\projectNumber1\env\Lib\site-packages\sqlalchemy\engine\default.py", line 700, in do_rollback
    dbapi_connection.rollback()
    ~~~~~~~~~~~~~~~~~~~~~~~~~^^
psycopg2.OperationalError: SSL connection has been closed unexpectedly

2025-02-16 20:31:04,445 - sqlalchemy.pool.impl.QueuePool - ERROR - Exception during reset or similar
Traceback (most recent call last):
  File "C:\Users\mayal\OneDrive\מסמכים\JB\pyt\SQLITE PCT\trying\projectNumber1\env\Lib\site-packages\sqlalchemy\pool\base.py", line 986, in _finalize_fairy
    fairy._reset(
    ~~~~~~~~~~~~^
        pool,
        ^^^^^
    ...<2 lines>...
        asyncio_safe=can_manipulate_connection,
        ^^^^^^^^^^^^^^^^^^^^^^^^^^^^^^^^^^^^^^^
    )
    ^
  File "C:\Users\mayal\OneDrive\מסמכים\JB\pyt\SQLITE PCT\trying\projectNumber1\env\Lib\site-packages\sqlalchemy\pool\base.py", line 1432, in _reset
    pool._dialect.do_rollback(self)
    ~~~~~~~~~~~~~~~~~~~~~~~~~^^^^^^
  File "C:\Users\mayal\OneDrive\מסמכים\JB\pyt\SQLITE PCT\trying\projectNumber1\env\Lib\site-packages\sqlalchemy\engine\default.py", line 700, in do_rollback
    dbapi_connection.rollback()
    ~~~~~~~~~~~~~~~~~~~~~~~~~^^
psycopg2.OperationalError: SSL connection has been closed unexpectedly

2025-02-16 20:31:04,446 - sqlalchemy.pool.impl.QueuePool - ERROR - Exception during reset or similar
Traceback (most recent call last):
  File "C:\Users\mayal\OneDrive\מסמכים\JB\pyt\SQLITE PCT\trying\projectNumber1\env\Lib\site-packages\sqlalchemy\pool\base.py", line 986, in _finalize_fairy
    fairy._reset(
    ~~~~~~~~~~~~^
        pool,
        ^^^^^
    ...<2 lines>...
        asyncio_safe=can_manipulate_connection,
        ^^^^^^^^^^^^^^^^^^^^^^^^^^^^^^^^^^^^^^^
    )
    ^
  File "C:\Users\mayal\OneDrive\מסמכים\JB\pyt\SQLITE PCT\trying\projectNumber1\env\Lib\site-packages\sqlalchemy\pool\base.py", line 1432, in _reset
    pool._dialect.do_rollback(self)
    ~~~~~~~~~~~~~~~~~~~~~~~~~^^^^^^
  File "C:\Users\mayal\OneDrive\מסמכים\JB\pyt\SQLITE PCT\trying\projectNumber1\env\Lib\site-packages\sqlalchemy\engine\default.py", line 700, in do_rollback
    dbapi_connection.rollback()
    ~~~~~~~~~~~~~~~~~~~~~~~~~^^
psycopg2.OperationalError: SSL connection has been closed unexpectedly

2025-02-16 20:31:04,448 - sqlalchemy.pool.impl.QueuePool - ERROR - Exception during reset or similar
Traceback (most recent call last):
  File "C:\Users\mayal\OneDrive\מסמכים\JB\pyt\SQLITE PCT\trying\projectNumber1\env\Lib\site-packages\sqlalchemy\pool\base.py", line 986, in _finalize_fairy
    fairy._reset(
    ~~~~~~~~~~~~^
        pool,
        ^^^^^
    ...<2 lines>...
        asyncio_safe=can_manipulate_connection,
        ^^^^^^^^^^^^^^^^^^^^^^^^^^^^^^^^^^^^^^^
    )
    ^
  File "C:\Users\mayal\OneDrive\מסמכים\JB\pyt\SQLITE PCT\trying\projectNumber1\env\Lib\site-packages\sqlalchemy\pool\base.py", line 1432, in _reset
    pool._dialect.do_rollback(self)
    ~~~~~~~~~~~~~~~~~~~~~~~~~^^^^^^
  File "C:\Users\mayal\OneDrive\מסמכים\JB\pyt\SQLITE PCT\trying\projectNumber1\env\Lib\site-packages\sqlalchemy\engine\default.py", line 700, in do_rollback
    dbapi_connection.rollback()
    ~~~~~~~~~~~~~~~~~~~~~~~~~^^
psycopg2.OperationalError: SSL connection has been closed unexpectedly

2025-02-16 20:31:04,449 - sqlalchemy.pool.impl.QueuePool - ERROR - Exception during reset or similar
Traceback (most recent call last):
  File "C:\Users\mayal\OneDrive\מסמכים\JB\pyt\SQLITE PCT\trying\projectNumber1\env\Lib\site-packages\sqlalchemy\pool\base.py", line 986, in _finalize_fairy
    fairy._reset(
    ~~~~~~~~~~~~^
        pool,
        ^^^^^
    ...<2 lines>...
        asyncio_safe=can_manipulate_connection,
        ^^^^^^^^^^^^^^^^^^^^^^^^^^^^^^^^^^^^^^^
    )
    ^
  File "C:\Users\mayal\OneDrive\מסמכים\JB\pyt\SQLITE PCT\trying\projectNumber1\env\Lib\site-packages\sqlalchemy\pool\base.py", line 1432, in _reset
    pool._dialect.do_rollback(self)
    ~~~~~~~~~~~~~~~~~~~~~~~~~^^^^^^
  File "C:\Users\mayal\OneDrive\מסמכים\JB\pyt\SQLITE PCT\trying\projectNumber1\env\Lib\site-packages\sqlalchemy\engine\default.py", line 700, in do_rollback
    dbapi_connection.rollback()
    ~~~~~~~~~~~~~~~~~~~~~~~~~^^
psycopg2.OperationalError: SSL connection has been closed unexpectedly

2025-02-16 20:31:04,450 - sqlalchemy.pool.impl.QueuePool - ERROR - Exception during reset or similar
Traceback (most recent call last):
  File "C:\Users\mayal\OneDrive\מסמכים\JB\pyt\SQLITE PCT\trying\projectNumber1\env\Lib\site-packages\sqlalchemy\pool\base.py", line 986, in _finalize_fairy
    fairy._reset(
    ~~~~~~~~~~~~^
        pool,
        ^^^^^
    ...<2 lines>...
        asyncio_safe=can_manipulate_connection,
        ^^^^^^^^^^^^^^^^^^^^^^^^^^^^^^^^^^^^^^^
    )
    ^
  File "C:\Users\mayal\OneDrive\מסמכים\JB\pyt\SQLITE PCT\trying\projectNumber1\env\Lib\site-packages\sqlalchemy\pool\base.py", line 1432, in _reset
    pool._dialect.do_rollback(self)
    ~~~~~~~~~~~~~~~~~~~~~~~~~^^^^^^
  File "C:\Users\mayal\OneDrive\מסמכים\JB\pyt\SQLITE PCT\trying\projectNumber1\env\Lib\site-packages\sqlalchemy\engine\default.py", line 700, in do_rollback
    dbapi_connection.rollback()
    ~~~~~~~~~~~~~~~~~~~~~~~~~^^
psycopg2.OperationalError: SSL connection has been closed unexpectedly

2025-02-16 20:31:04,451 - sqlalchemy.pool.impl.QueuePool - ERROR - Exception during reset or similar
Traceback (most recent call last):
  File "C:\Users\mayal\OneDrive\מסמכים\JB\pyt\SQLITE PCT\trying\projectNumber1\env\Lib\site-packages\sqlalchemy\pool\base.py", line 986, in _finalize_fairy
    fairy._reset(
    ~~~~~~~~~~~~^
        pool,
        ^^^^^
    ...<2 lines>...
        asyncio_safe=can_manipulate_connection,
        ^^^^^^^^^^^^^^^^^^^^^^^^^^^^^^^^^^^^^^^
    )
    ^
  File "C:\Users\mayal\OneDrive\מסמכים\JB\pyt\SQLITE PCT\trying\projectNumber1\env\Lib\site-packages\sqlalchemy\pool\base.py", line 1432, in _reset
    pool._dialect.do_rollback(self)
    ~~~~~~~~~~~~~~~~~~~~~~~~~^^^^^^
  File "C:\Users\mayal\OneDrive\מסמכים\JB\pyt\SQLITE PCT\trying\projectNumber1\env\Lib\site-packages\sqlalchemy\engine\default.py", line 700, in do_rollback
    dbapi_connection.rollback()
    ~~~~~~~~~~~~~~~~~~~~~~~~~^^
psycopg2.OperationalError: SSL connection has been closed unexpectedly

2025-02-16 20:31:04,452 - sqlalchemy.pool.impl.QueuePool - ERROR - Exception during reset or similar
Traceback (most recent call last):
  File "C:\Users\mayal\OneDrive\מסמכים\JB\pyt\SQLITE PCT\trying\projectNumber1\env\Lib\site-packages\sqlalchemy\pool\base.py", line 986, in _finalize_fairy
    fairy._reset(
    ~~~~~~~~~~~~^
        pool,
        ^^^^^
    ...<2 lines>...
        asyncio_safe=can_manipulate_connection,
        ^^^^^^^^^^^^^^^^^^^^^^^^^^^^^^^^^^^^^^^
    )
    ^
  File "C:\Users\mayal\OneDrive\מסמכים\JB\pyt\SQLITE PCT\trying\projectNumber1\env\Lib\site-packages\sqlalchemy\pool\base.py", line 1432, in _reset
    pool._dialect.do_rollback(self)
    ~~~~~~~~~~~~~~~~~~~~~~~~~^^^^^^
  File "C:\Users\mayal\OneDrive\מסמכים\JB\pyt\SQLITE PCT\trying\projectNumber1\env\Lib\site-packages\sqlalchemy\engine\default.py", line 700, in do_rollback
    dbapi_connection.rollback()
    ~~~~~~~~~~~~~~~~~~~~~~~~~^^
psycopg2.OperationalError: SSL connection has been closed unexpectedly

2025-02-16 20:31:04,453 - sqlalchemy.pool.impl.QueuePool - ERROR - Exception during reset or similar
Traceback (most recent call last):
  File "C:\Users\mayal\OneDrive\מסמכים\JB\pyt\SQLITE PCT\trying\projectNumber1\env\Lib\site-packages\sqlalchemy\pool\base.py", line 986, in _finalize_fairy
    fairy._reset(
    ~~~~~~~~~~~~^
        pool,
        ^^^^^
    ...<2 lines>...
        asyncio_safe=can_manipulate_connection,
        ^^^^^^^^^^^^^^^^^^^^^^^^^^^^^^^^^^^^^^^
    )
    ^
  File "C:\Users\mayal\OneDrive\מסמכים\JB\pyt\SQLITE PCT\trying\projectNumber1\env\Lib\site-packages\sqlalchemy\pool\base.py", line 1432, in _reset
    pool._dialect.do_rollback(self)
    ~~~~~~~~~~~~~~~~~~~~~~~~~^^^^^^
  File "C:\Users\mayal\OneDrive\מסמכים\JB\pyt\SQLITE PCT\trying\projectNumber1\env\Lib\site-packages\sqlalchemy\engine\default.py", line 700, in do_rollback
    dbapi_connection.rollback()
    ~~~~~~~~~~~~~~~~~~~~~~~~~^^
psycopg2.OperationalError: SSL connection has been closed unexpectedly

2025-02-16 20:31:04,454 - sqlalchemy.pool.impl.QueuePool - ERROR - Exception during reset or similar
Traceback (most recent call last):
  File "C:\Users\mayal\OneDrive\מסמכים\JB\pyt\SQLITE PCT\trying\projectNumber1\env\Lib\site-packages\sqlalchemy\pool\base.py", line 986, in _finalize_fairy
    fairy._reset(
    ~~~~~~~~~~~~^
        pool,
        ^^^^^
    ...<2 lines>...
        asyncio_safe=can_manipulate_connection,
        ^^^^^^^^^^^^^^^^^^^^^^^^^^^^^^^^^^^^^^^
    )
    ^
  File "C:\Users\mayal\OneDrive\מסמכים\JB\pyt\SQLITE PCT\trying\projectNumber1\env\Lib\site-packages\sqlalchemy\pool\base.py", line 1432, in _reset
    pool._dialect.do_rollback(self)
    ~~~~~~~~~~~~~~~~~~~~~~~~~^^^^^^
  File "C:\Users\mayal\OneDrive\מסמכים\JB\pyt\SQLITE PCT\trying\projectNumber1\env\Lib\site-packages\sqlalchemy\engine\default.py", line 700, in do_rollback
    dbapi_connection.rollback()
    ~~~~~~~~~~~~~~~~~~~~~~~~~^^
psycopg2.OperationalError: SSL connection has been closed unexpectedly

2025-02-16 20:31:04,455 - sqlalchemy.pool.impl.QueuePool - ERROR - Exception during reset or similar
Traceback (most recent call last):
  File "C:\Users\mayal\OneDrive\מסמכים\JB\pyt\SQLITE PCT\trying\projectNumber1\env\Lib\site-packages\sqlalchemy\pool\base.py", line 986, in _finalize_fairy
    fairy._reset(
    ~~~~~~~~~~~~^
        pool,
        ^^^^^
    ...<2 lines>...
        asyncio_safe=can_manipulate_connection,
        ^^^^^^^^^^^^^^^^^^^^^^^^^^^^^^^^^^^^^^^
    )
    ^
  File "C:\Users\mayal\OneDrive\מסמכים\JB\pyt\SQLITE PCT\trying\projectNumber1\env\Lib\site-packages\sqlalchemy\pool\base.py", line 1432, in _reset
    pool._dialect.do_rollback(self)
    ~~~~~~~~~~~~~~~~~~~~~~~~~^^^^^^
  File "C:\Users\mayal\OneDrive\מסמכים\JB\pyt\SQLITE PCT\trying\projectNumber1\env\Lib\site-packages\sqlalchemy\engine\default.py", line 700, in do_rollback
    dbapi_connection.rollback()
    ~~~~~~~~~~~~~~~~~~~~~~~~~^^
psycopg2.OperationalError: SSL connection has been closed unexpectedly

2025-02-16 20:31:04,456 - sqlalchemy.pool.impl.QueuePool - ERROR - Exception during reset or similar
Traceback (most recent call last):
  File "C:\Users\mayal\OneDrive\מסמכים\JB\pyt\SQLITE PCT\trying\projectNumber1\env\Lib\site-packages\sqlalchemy\pool\base.py", line 986, in _finalize_fairy
    fairy._reset(
    ~~~~~~~~~~~~^
        pool,
        ^^^^^
    ...<2 lines>...
        asyncio_safe=can_manipulate_connection,
        ^^^^^^^^^^^^^^^^^^^^^^^^^^^^^^^^^^^^^^^
    )
    ^
  File "C:\Users\mayal\OneDrive\מסמכים\JB\pyt\SQLITE PCT\trying\projectNumber1\env\Lib\site-packages\sqlalchemy\pool\base.py", line 1432, in _reset
    pool._dialect.do_rollback(self)
    ~~~~~~~~~~~~~~~~~~~~~~~~~^^^^^^
  File "C:\Users\mayal\OneDrive\מסמכים\JB\pyt\SQLITE PCT\trying\projectNumber1\env\Lib\site-packages\sqlalchemy\engine\default.py", line 700, in do_rollback
    dbapi_connection.rollback()
    ~~~~~~~~~~~~~~~~~~~~~~~~~^^
psycopg2.OperationalError: SSL connection has been closed unexpectedly

2025-02-16 20:31:38,687 - my log - INFO - Loan types seeded successfully!
2025-02-16 20:33:05,207 - my log - INFO - Fetched 2 customers based on search filters
2025-02-16 20:33:05,211 - my log - INFO - Fetched all late loans
2025-02-16 20:33:05,215 - my log - INFO - Fetched all active loans
2025-02-16 20:33:16,060 - my log - INFO - Updated book: <Book(id=14, name=Percy Jackson & the Olympians: The Sea of Monsters, author=Rick Rairden, publishYear=2007, bookLoanType=2, isLoaned=True, active=True)>
2025-02-16 20:33:16,356 - my log - INFO - Fetched all active loans
2025-02-16 20:36:20,478 - my log - INFO - Fetched all late loans
2025-02-16 20:36:20,492 - my log - INFO - Fetched all active loans
2025-02-16 20:36:20,502 - my log - INFO - Fetched 2 customers based on search filters
2025-02-16 20:36:49,358 - my log - INFO - Fetched all active loans
2025-02-16 20:36:49,379 - my log - INFO - Fetched 2 customers based on search filters
2025-02-16 20:36:49,396 - my log - INFO - Fetched all late loans
2025-02-16 20:36:51,330 - my log - INFO - Fetched 2 customers based on search filters
2025-02-16 20:36:51,331 - my log - INFO - Fetched all active loans
2025-02-16 20:36:51,937 - my log - INFO - Fetched all late loans
2025-02-16 20:36:51,951 - my log - INFO - Fetched 2 customers based on search filters
2025-02-16 20:36:51,952 - my log - INFO - Fetched all late loans
2025-02-16 20:36:51,953 - my log - INFO - Fetched all active loans
2025-02-16 20:36:53,481 - my log - INFO - Fetched 2 customers based on search filters
2025-02-16 20:36:53,482 - my log - INFO - Fetched all active loans
2025-02-16 20:36:53,495 - my log - INFO - Fetched all late loans
2025-02-16 20:37:15,996 - my log - INFO - Fetched all active loans
2025-02-16 20:37:16,017 - my log - INFO - Fetched all late loans
2025-02-16 20:37:16,018 - my log - INFO - Fetched 2 customers based on search filters
2025-02-16 20:37:24,469 - my log - INFO - Fetched 2 customers based on search filters
2025-02-16 20:37:24,503 - my log - INFO - Fetched all active loans
2025-02-16 20:37:24,504 - my log - INFO - Fetched all late loans
2025-02-16 20:37:27,732 - my log - INFO - Fetched 2 customers based on search filters
2025-02-16 20:37:27,736 - my log - INFO - Fetched all active loans
2025-02-16 20:37:27,738 - my log - INFO - Fetched all late loans
2025-02-16 20:37:36,024 - my log - INFO - Fetched 2 customers based on search filters
2025-02-16 20:37:36,032 - my log - INFO - Fetched all active loans
2025-02-16 20:37:36,040 - my log - INFO - Fetched all late loans
2025-02-16 20:37:50,315 - my log - INFO - Fetched 2 customers based on search filters
2025-02-16 20:37:50,316 - my log - INFO - Fetched all late loans
2025-02-16 20:37:50,318 - my log - INFO - Fetched all active loans
2025-02-16 20:37:55,433 - my log - INFO - Fetched 2 customers based on search filters
2025-02-16 20:37:56,352 - my log - INFO - Fetched all active loans
2025-02-16 20:37:56,362 - my log - INFO - Fetched all late loans
2025-02-16 20:37:58,918 - my log - INFO - Fetched all late loans
2025-02-16 20:37:59,001 - my log - INFO - Fetched 2 customers based on search filters
2025-02-16 20:37:59,004 - my log - INFO - Fetched all active loans
2025-02-16 20:38:11,283 - my log - INFO - Fetched 2 customers based on search filters
2025-02-16 20:38:11,323 - my log - INFO - Fetched all active loans
2025-02-16 20:38:26,015 - my log - INFO - Fetched all late loans
2025-02-16 20:38:26,296 - my log - INFO - Fetched 2 customers based on search filters
2025-02-16 20:38:26,453 - my log - INFO - Fetched all late loans
2025-02-16 20:38:28,674 - my log - INFO - Fetched all active loans
2025-02-16 20:38:31,902 - my log - INFO - Fetched all active loans
2025-02-16 20:38:31,905 - my log - INFO - Fetched 2 customers based on search filters
2025-02-16 20:38:31,906 - my log - INFO - Fetched all late loans
2025-02-16 20:38:32,924 - my log - INFO - Fetched all late loans
2025-02-16 20:38:32,931 - my log - INFO - Fetched all active loans
2025-02-16 20:38:32,932 - my log - INFO - Fetched 2 customers based on search filters
2025-02-16 20:39:58,753 - my log - INFO - Fetched all late loans
2025-02-16 20:39:58,856 - my log - INFO - Fetched all active loans
2025-02-16 20:39:58,891 - my log - INFO - Fetched 2 customers based on search filters
2025-02-16 20:40:06,825 - my log - INFO - Fetched 2 customers based on search filters
2025-02-16 20:40:35,606 - my log - ERROR - Error in loans endpoint: QueuePool limit of size 10 overflow 20 reached, connection timed out, timeout 30.00 (Background on this error at: https://sqlalche.me/e/20/3o7r)
2025-02-16 20:40:35,607 - my log - ERROR - Error in lateLoans endpoint: QueuePool limit of size 10 overflow 20 reached, connection timed out, timeout 30.00 (Background on this error at: https://sqlalche.me/e/20/3o7r)
2025-02-16 20:42:30,953 - my log - INFO - Fetched 2 customers based on search filters
2025-02-16 20:42:31,081 - my log - INFO - Fetched all active loans
2025-02-16 20:42:31,236 - my log - INFO - Fetched all late loans
2025-02-16 20:42:31,517 - my log - INFO - Fetched 2 customers based on search filters
2025-02-16 20:42:32,943 - my log - INFO - Fetched all active loans
2025-02-16 20:42:32,945 - my log - INFO - Fetched all late loans
2025-02-16 20:42:36,406 - sqlalchemy.pool.impl.QueuePool - ERROR - Exception during reset or similar
Traceback (most recent call last):
  File "C:\Users\mayal\OneDrive\מסמכים\JB\pyt\SQLITE PCT\trying\projectNumber1\env\Lib\site-packages\sqlalchemy\pool\base.py", line 986, in _finalize_fairy
    fairy._reset(
    ~~~~~~~~~~~~^
        pool,
        ^^^^^
    ...<2 lines>...
        asyncio_safe=can_manipulate_connection,
        ^^^^^^^^^^^^^^^^^^^^^^^^^^^^^^^^^^^^^^^
    )
    ^
  File "C:\Users\mayal\OneDrive\מסמכים\JB\pyt\SQLITE PCT\trying\projectNumber1\env\Lib\site-packages\sqlalchemy\pool\base.py", line 1432, in _reset
    pool._dialect.do_rollback(self)
    ~~~~~~~~~~~~~~~~~~~~~~~~~^^^^^^
  File "C:\Users\mayal\OneDrive\מסמכים\JB\pyt\SQLITE PCT\trying\projectNumber1\env\Lib\site-packages\sqlalchemy\engine\default.py", line 700, in do_rollback
    dbapi_connection.rollback()
    ~~~~~~~~~~~~~~~~~~~~~~~~~^^
psycopg2.OperationalError: SSL connection has been closed unexpectedly

2025-02-16 20:42:36,409 - sqlalchemy.pool.impl.QueuePool - ERROR - Exception during reset or similar
Traceback (most recent call last):
  File "C:\Users\mayal\OneDrive\מסמכים\JB\pyt\SQLITE PCT\trying\projectNumber1\env\Lib\site-packages\sqlalchemy\pool\base.py", line 986, in _finalize_fairy
    fairy._reset(
    ~~~~~~~~~~~~^
        pool,
        ^^^^^
    ...<2 lines>...
        asyncio_safe=can_manipulate_connection,
        ^^^^^^^^^^^^^^^^^^^^^^^^^^^^^^^^^^^^^^^
    )
    ^
  File "C:\Users\mayal\OneDrive\מסמכים\JB\pyt\SQLITE PCT\trying\projectNumber1\env\Lib\site-packages\sqlalchemy\pool\base.py", line 1432, in _reset
    pool._dialect.do_rollback(self)
    ~~~~~~~~~~~~~~~~~~~~~~~~~^^^^^^
  File "C:\Users\mayal\OneDrive\מסמכים\JB\pyt\SQLITE PCT\trying\projectNumber1\env\Lib\site-packages\sqlalchemy\engine\default.py", line 700, in do_rollback
    dbapi_connection.rollback()
    ~~~~~~~~~~~~~~~~~~~~~~~~~^^
psycopg2.OperationalError: SSL connection has been closed unexpectedly

2025-02-16 20:42:36,410 - sqlalchemy.pool.impl.QueuePool - ERROR - Exception during reset or similar
Traceback (most recent call last):
  File "C:\Users\mayal\OneDrive\מסמכים\JB\pyt\SQLITE PCT\trying\projectNumber1\env\Lib\site-packages\sqlalchemy\pool\base.py", line 986, in _finalize_fairy
    fairy._reset(
    ~~~~~~~~~~~~^
        pool,
        ^^^^^
    ...<2 lines>...
        asyncio_safe=can_manipulate_connection,
        ^^^^^^^^^^^^^^^^^^^^^^^^^^^^^^^^^^^^^^^
    )
    ^
  File "C:\Users\mayal\OneDrive\מסמכים\JB\pyt\SQLITE PCT\trying\projectNumber1\env\Lib\site-packages\sqlalchemy\pool\base.py", line 1432, in _reset
    pool._dialect.do_rollback(self)
    ~~~~~~~~~~~~~~~~~~~~~~~~~^^^^^^
  File "C:\Users\mayal\OneDrive\מסמכים\JB\pyt\SQLITE PCT\trying\projectNumber1\env\Lib\site-packages\sqlalchemy\engine\default.py", line 700, in do_rollback
    dbapi_connection.rollback()
    ~~~~~~~~~~~~~~~~~~~~~~~~~^^
psycopg2.OperationalError: SSL connection has been closed unexpectedly

2025-02-16 20:42:36,411 - sqlalchemy.pool.impl.QueuePool - ERROR - Exception during reset or similar
Traceback (most recent call last):
  File "C:\Users\mayal\OneDrive\מסמכים\JB\pyt\SQLITE PCT\trying\projectNumber1\env\Lib\site-packages\sqlalchemy\pool\base.py", line 986, in _finalize_fairy
    fairy._reset(
    ~~~~~~~~~~~~^
        pool,
        ^^^^^
    ...<2 lines>...
        asyncio_safe=can_manipulate_connection,
        ^^^^^^^^^^^^^^^^^^^^^^^^^^^^^^^^^^^^^^^
    )
    ^
  File "C:\Users\mayal\OneDrive\מסמכים\JB\pyt\SQLITE PCT\trying\projectNumber1\env\Lib\site-packages\sqlalchemy\pool\base.py", line 1432, in _reset
    pool._dialect.do_rollback(self)
    ~~~~~~~~~~~~~~~~~~~~~~~~~^^^^^^
  File "C:\Users\mayal\OneDrive\מסמכים\JB\pyt\SQLITE PCT\trying\projectNumber1\env\Lib\site-packages\sqlalchemy\engine\default.py", line 700, in do_rollback
    dbapi_connection.rollback()
    ~~~~~~~~~~~~~~~~~~~~~~~~~^^
psycopg2.OperationalError: SSL connection has been closed unexpectedly

2025-02-16 20:42:36,412 - sqlalchemy.pool.impl.QueuePool - ERROR - Exception during reset or similar
Traceback (most recent call last):
  File "C:\Users\mayal\OneDrive\מסמכים\JB\pyt\SQLITE PCT\trying\projectNumber1\env\Lib\site-packages\sqlalchemy\pool\base.py", line 986, in _finalize_fairy
    fairy._reset(
    ~~~~~~~~~~~~^
        pool,
        ^^^^^
    ...<2 lines>...
        asyncio_safe=can_manipulate_connection,
        ^^^^^^^^^^^^^^^^^^^^^^^^^^^^^^^^^^^^^^^
    )
    ^
  File "C:\Users\mayal\OneDrive\מסמכים\JB\pyt\SQLITE PCT\trying\projectNumber1\env\Lib\site-packages\sqlalchemy\pool\base.py", line 1432, in _reset
    pool._dialect.do_rollback(self)
    ~~~~~~~~~~~~~~~~~~~~~~~~~^^^^^^
  File "C:\Users\mayal\OneDrive\מסמכים\JB\pyt\SQLITE PCT\trying\projectNumber1\env\Lib\site-packages\sqlalchemy\engine\default.py", line 700, in do_rollback
    dbapi_connection.rollback()
    ~~~~~~~~~~~~~~~~~~~~~~~~~^^
psycopg2.OperationalError: SSL connection has been closed unexpectedly

2025-02-16 20:42:36,413 - sqlalchemy.pool.impl.QueuePool - ERROR - Exception during reset or similar
Traceback (most recent call last):
  File "C:\Users\mayal\OneDrive\מסמכים\JB\pyt\SQLITE PCT\trying\projectNumber1\env\Lib\site-packages\sqlalchemy\pool\base.py", line 986, in _finalize_fairy
    fairy._reset(
    ~~~~~~~~~~~~^
        pool,
        ^^^^^
    ...<2 lines>...
        asyncio_safe=can_manipulate_connection,
        ^^^^^^^^^^^^^^^^^^^^^^^^^^^^^^^^^^^^^^^
    )
    ^
  File "C:\Users\mayal\OneDrive\מסמכים\JB\pyt\SQLITE PCT\trying\projectNumber1\env\Lib\site-packages\sqlalchemy\pool\base.py", line 1432, in _reset
    pool._dialect.do_rollback(self)
    ~~~~~~~~~~~~~~~~~~~~~~~~~^^^^^^
  File "C:\Users\mayal\OneDrive\מסמכים\JB\pyt\SQLITE PCT\trying\projectNumber1\env\Lib\site-packages\sqlalchemy\engine\default.py", line 700, in do_rollback
    dbapi_connection.rollback()
    ~~~~~~~~~~~~~~~~~~~~~~~~~^^
psycopg2.OperationalError: SSL connection has been closed unexpectedly

2025-02-16 20:42:36,414 - sqlalchemy.pool.impl.QueuePool - ERROR - Exception during reset or similar
Traceback (most recent call last):
  File "C:\Users\mayal\OneDrive\מסמכים\JB\pyt\SQLITE PCT\trying\projectNumber1\env\Lib\site-packages\sqlalchemy\pool\base.py", line 986, in _finalize_fairy
    fairy._reset(
    ~~~~~~~~~~~~^
        pool,
        ^^^^^
    ...<2 lines>...
        asyncio_safe=can_manipulate_connection,
        ^^^^^^^^^^^^^^^^^^^^^^^^^^^^^^^^^^^^^^^
    )
    ^
  File "C:\Users\mayal\OneDrive\מסמכים\JB\pyt\SQLITE PCT\trying\projectNumber1\env\Lib\site-packages\sqlalchemy\pool\base.py", line 1432, in _reset
    pool._dialect.do_rollback(self)
    ~~~~~~~~~~~~~~~~~~~~~~~~~^^^^^^
  File "C:\Users\mayal\OneDrive\מסמכים\JB\pyt\SQLITE PCT\trying\projectNumber1\env\Lib\site-packages\sqlalchemy\engine\default.py", line 700, in do_rollback
    dbapi_connection.rollback()
    ~~~~~~~~~~~~~~~~~~~~~~~~~^^
psycopg2.OperationalError: SSL connection has been closed unexpectedly

2025-02-16 20:42:36,415 - sqlalchemy.pool.impl.QueuePool - ERROR - Exception during reset or similar
Traceback (most recent call last):
  File "C:\Users\mayal\OneDrive\מסמכים\JB\pyt\SQLITE PCT\trying\projectNumber1\env\Lib\site-packages\sqlalchemy\pool\base.py", line 986, in _finalize_fairy
    fairy._reset(
    ~~~~~~~~~~~~^
        pool,
        ^^^^^
    ...<2 lines>...
        asyncio_safe=can_manipulate_connection,
        ^^^^^^^^^^^^^^^^^^^^^^^^^^^^^^^^^^^^^^^
    )
    ^
  File "C:\Users\mayal\OneDrive\מסמכים\JB\pyt\SQLITE PCT\trying\projectNumber1\env\Lib\site-packages\sqlalchemy\pool\base.py", line 1432, in _reset
    pool._dialect.do_rollback(self)
    ~~~~~~~~~~~~~~~~~~~~~~~~~^^^^^^
  File "C:\Users\mayal\OneDrive\מסמכים\JB\pyt\SQLITE PCT\trying\projectNumber1\env\Lib\site-packages\sqlalchemy\engine\default.py", line 700, in do_rollback
    dbapi_connection.rollback()
    ~~~~~~~~~~~~~~~~~~~~~~~~~^^
psycopg2.OperationalError: SSL connection has been closed unexpectedly

2025-02-16 20:42:36,416 - sqlalchemy.pool.impl.QueuePool - ERROR - Exception during reset or similar
Traceback (most recent call last):
  File "C:\Users\mayal\OneDrive\מסמכים\JB\pyt\SQLITE PCT\trying\projectNumber1\env\Lib\site-packages\sqlalchemy\pool\base.py", line 986, in _finalize_fairy
    fairy._reset(
    ~~~~~~~~~~~~^
        pool,
        ^^^^^
    ...<2 lines>...
        asyncio_safe=can_manipulate_connection,
        ^^^^^^^^^^^^^^^^^^^^^^^^^^^^^^^^^^^^^^^
    )
    ^
  File "C:\Users\mayal\OneDrive\מסמכים\JB\pyt\SQLITE PCT\trying\projectNumber1\env\Lib\site-packages\sqlalchemy\pool\base.py", line 1432, in _reset
    pool._dialect.do_rollback(self)
    ~~~~~~~~~~~~~~~~~~~~~~~~~^^^^^^
  File "C:\Users\mayal\OneDrive\מסמכים\JB\pyt\SQLITE PCT\trying\projectNumber1\env\Lib\site-packages\sqlalchemy\engine\default.py", line 700, in do_rollback
    dbapi_connection.rollback()
    ~~~~~~~~~~~~~~~~~~~~~~~~~^^
psycopg2.OperationalError: SSL connection has been closed unexpectedly

2025-02-16 20:42:36,416 - sqlalchemy.pool.impl.QueuePool - ERROR - Exception during reset or similar
Traceback (most recent call last):
  File "C:\Users\mayal\OneDrive\מסמכים\JB\pyt\SQLITE PCT\trying\projectNumber1\env\Lib\site-packages\sqlalchemy\pool\base.py", line 986, in _finalize_fairy
    fairy._reset(
    ~~~~~~~~~~~~^
        pool,
        ^^^^^
    ...<2 lines>...
        asyncio_safe=can_manipulate_connection,
        ^^^^^^^^^^^^^^^^^^^^^^^^^^^^^^^^^^^^^^^
    )
    ^
  File "C:\Users\mayal\OneDrive\מסמכים\JB\pyt\SQLITE PCT\trying\projectNumber1\env\Lib\site-packages\sqlalchemy\pool\base.py", line 1432, in _reset
    pool._dialect.do_rollback(self)
    ~~~~~~~~~~~~~~~~~~~~~~~~~^^^^^^
  File "C:\Users\mayal\OneDrive\מסמכים\JB\pyt\SQLITE PCT\trying\projectNumber1\env\Lib\site-packages\sqlalchemy\engine\default.py", line 700, in do_rollback
    dbapi_connection.rollback()
    ~~~~~~~~~~~~~~~~~~~~~~~~~^^
psycopg2.OperationalError: SSL connection has been closed unexpectedly

2025-02-16 20:42:36,417 - sqlalchemy.pool.impl.QueuePool - ERROR - Exception during reset or similar
Traceback (most recent call last):
  File "C:\Users\mayal\OneDrive\מסמכים\JB\pyt\SQLITE PCT\trying\projectNumber1\env\Lib\site-packages\sqlalchemy\pool\base.py", line 986, in _finalize_fairy
    fairy._reset(
    ~~~~~~~~~~~~^
        pool,
        ^^^^^
    ...<2 lines>...
        asyncio_safe=can_manipulate_connection,
        ^^^^^^^^^^^^^^^^^^^^^^^^^^^^^^^^^^^^^^^
    )
    ^
  File "C:\Users\mayal\OneDrive\מסמכים\JB\pyt\SQLITE PCT\trying\projectNumber1\env\Lib\site-packages\sqlalchemy\pool\base.py", line 1432, in _reset
    pool._dialect.do_rollback(self)
    ~~~~~~~~~~~~~~~~~~~~~~~~~^^^^^^
  File "C:\Users\mayal\OneDrive\מסמכים\JB\pyt\SQLITE PCT\trying\projectNumber1\env\Lib\site-packages\sqlalchemy\engine\default.py", line 700, in do_rollback
    dbapi_connection.rollback()
    ~~~~~~~~~~~~~~~~~~~~~~~~~^^
psycopg2.OperationalError: SSL connection has been closed unexpectedly

2025-02-16 20:42:42,226 - my log - INFO - Loan types already seeded!
2025-02-16 20:42:48,743 - my log - INFO - Fetched all active loans
2025-02-16 20:42:48,754 - my log - INFO - Fetched all late loans
2025-02-16 20:42:48,883 - my log - INFO - Fetched 2 customers based on search filters
2025-02-16 20:42:53,360 - my log - INFO - Login endpoint accessed
2025-02-16 20:42:54,779 - my log - INFO - Login successful for username: maya
2025-02-16 20:42:54,793 - my log - INFO - Manager dashboard accessed by username: maya
2025-02-16 20:42:55,948 - my log - INFO - Manager dashboard access granted for username: maya
2025-02-16 20:42:56,707 - my log - INFO - Fetched all active loans
2025-02-16 20:42:57,273 - my log - INFO - Fetched all late loans
2025-02-16 20:42:57,275 - my log - INFO - Fetched 2 customers based on search filters
2025-02-16 20:43:32,347 - my log - INFO - Fetched 2 customers based on search filters
2025-02-16 20:43:32,364 - my log - INFO - Fetched all late loans
2025-02-16 20:43:32,369 - my log - INFO - Fetched all active loans
